Workbook

Sheet 설명
A1: 매체 접점별 인지·호감·구매 영향 통합 (2017–2019)
A3: 목적 | B3: 소비자가 브랜드를 알게 되고(인지), 호감을 갖고(호감), 구매하는(구매) 단계에서 어떤 매체·접점이 가장 큰 영향을 주는지 3개 연도(2017·2018·2019)를 모두 비교한다.
A4: 원본 | B4: 시계열_매체_접점-인지.xlsx / -호감.xlsx / -구매.xlsx (사용자 제공). 원본 파일에는 출처·문항 문구·단위가 적혀 있지 않다.
A5: 출처 입력 | B5: (원본 출처를 여기에 입력하세요)
A6: 단위 | B6: 원본 값은 비율(%)로 보인다. 접점 비율의 합이 100%를 크게 넘으므로 복수응답으로 추정된다. 정확한 문항·단위는 원자료 출처에서 확인해야 한다.
A7: 사례수 | B7: 2017년 5,000명, 2018년 4,000명, 2019년 4,000명 (원본 기재, 인지 파일의 '4000명' 표기는 '4,000명'으로 통일).
A8: 정리 방법 | B8: ① 3개 파일의 같은 접점을 한 행으로 합침 ② 문자열로 저장된 숫자를 수치로 변환 ③ 3개 파일 모두 값이 없는 48개 행(과거 문항 이름만 남은 행, 예: '지상파 TV 광고', 'QR코드', '없음')은 제외, 접점 34개만 남김.
A9: 빈칸 | B9: 원본에서 비어 있어 빈칸으로 둔 곳: 2017 인지의 'TV PPL', 2019년 '게임 또는 스포츠 팀 후원'(인지·호감·구매 모두). 해당 연도의 순위는 33개 접점 중 순위가 되며, 평균은 값이 있는 연도만으로 계산된다('순위_안정성'의 '구매 자료 연수' 참고).
A10: 구분(분류) | B10: '통합데이터' 시트의 구분(TV·라디오, 인쇄·DM 등 7개)은 원본에 없고 작성 과정에서 임의로 묶은 것이다. A열을 고치면 '구분별_평균'이 자동으로 바뀐다.
A11: 주의 1 | B11: 2017→2018 사이에 일부 접점이 급변한다(예: 인지의 '회사의 사회공헌' 61.8→14.1, '건물 외벽/옥상…' 14.4→42.0). 설문 문항·보기 개편 때문일 가능성이 있어 '3개년_추이'에서 표시했다. 2017년과 2018~2019년을 직접 비교할 때는 주의가 필요하고, 그래서 '순위_안정성'에 2018~2019 평균을 따로 두었다.
A12: 주의 2 | B12: '구매÷인지(배)'는 전환율이 아니다. 단계마다 응답 기준이 달라 1배를 넘을 수 있으며(예: 주변사람 추천), 접점의 상대적 구매 영향력을 보는 참고 지표다.
A13: 주의 3 | B13: '3단계 평균'은 인지·호감·구매 비율의 단순 평균으로, 세 단계를 동일 비중으로 본다는 가정이 들어 있다. 구매 영향이 목적이면 '구매' 순위를 우선 본다.
A14: 시트 안내 | B14: 통합데이터(정리된 원자료) · 2017/2018/2019_접점비교(연도별 비교·순위) · TOP10_요약(연도별 단계별 상위 10) · 순위_안정성(3개년 순위 변화·평균) · 3개년_추이(변화폭) · 구분별_평균(분류별 3개년 요약·차트)

Sheet 통합데이터
A1: 접점별 인지·호감·구매 비율 (%) — 2017~2019
A2: 원본 3개 파일을 접점 기준으로 합친 표. 빈칸은 원본에 값이 없는 항목.
A4: 구분 | B4: 접점(매체) | C4: ① 인지 | F4: ② 호감 | I4: ③ 구매
C5: 2017 | D5: 2018 | E5: 2019 | F5: 2017 | G5: 2018 | H5: 2019 | I5: 2017 | J5: 2018 | K5: 2019
A6: 사례수 | B6: (명) | C6: 5000 | D6: 4000 | E6: 4000 | F6: 5000 | G6: 4000 | H6: 4000 | I6: 5000 | J6: 4000 | K6: 4000
A7: TV·라디오 | B7: TV 광고 | C7: 77.7 | D7: 75.8 | E7: 82.3 | F7: 62.6 | G7: 60.4 | H7: 58.4 | I7: 51.6 | J7: 43.4 | K7: 47.1
A8: TV·라디오 | B8: 드라마 등 TV프로그램 속 간접광고(PPL) | D8: 44.2 | E8: 42.4 | F8: 33.4 | G8: 36.3 | H8: 34.8 | I8: 20.7 | J8: 20.5 | K8: 17.1
A9: TV·라디오 | B9: 라디오 광고 | C9: 34 | D9: 25.2 | E9: 25.7 | F9: 9.5 | G9: 10.4 | H9: 10.1 | I9: 4.9 | J9: 6.2 | K9: 6.1
A10: 인쇄·DM | B10: 신문 광고 | C10: 15.4 | D10: 21.9 | E10: 18.3 | F10: 12.9 | G10: 8.3 | H10: 7.3 | I10: 7 | J10: 4.7 | K10: 4
A11: 인쇄·DM | B11: 신문 기사 | C11: 17.5 | D11: 14.4 | E11: 13 | F11: 11.1 | G11: 7.4 | H11: 6.8 | I11: 7.7 | J11: 5.9 | K11: 4.2
A12: 인쇄·DM | B12: 잡지 광고 | C12: 16.2 | D12: 19.1 | E12: 16.6 | F12: 18.7 | G12: 13.4 | H12: 14.4 | I12: 7.7 | J12: 4.8 | K12: 5
A13: 인쇄·DM | B13: 잡지 기사 | C13: 15.1 | D13: 13.8 | E13: 11 | F13: 12.4 | G13: 8 | H13: 8.8 | I13: 8.6 | J13: 5.6 | K13: 4.7
A14: 인쇄·DM | B14: 제품 카달로그/전단지 | C14: 14 | D14: 37 | E14: 41.5 | F14: 26.7 | G14: 26.1 | H14: 26.7 | I14: 19.3 | J14: 20.3 | K14: 19.6
A15: 인쇄·DM | B15: 광고 우편물/명세서 등 | C15: 35.2 | D15: 25.9 | E15: 26.9 | F15: 14.2 | G15: 13 | H15: 11.6 | I15: 8.6 | J15: 9.5 | K15: 7.7
A16: 온라인·디지털 | B16: 배너 광고 | C16: 24 | D16: 23.6 | E16: 23.5 | F16: 13.6 | G16: 9 | H16: 7.7 | I16: 6.2 | J16: 4.1 | K16: 3.5
A17: 온라인·디지털 | B17: 팝업 광고 | C17: 18.3 | D17: 21.6 | E17: 20.4 | F17: 12.4 | G17: 8.1 | H17: 7.1 | I17: 6.4 | J17: 3.4 | K17: 3
A18: 온라인·디지털 | B18: 동영상 광고 (동영상 재생 전후 등) | C18: 16.6 | D18: 23.4 | E18: 23.5 | F18: 17 | G18: 12.2 | H18: 13.4 | I18: 10.2 | J18: 5.3 | K18: 6
A19: 온라인·디지털 | B19: 검색어/키워드 광고 | C19: 19.3 | D19: 20.4 | E19: 22.8 | F19: 14.7 | G19: 8.8 | H19: 8.8 | I19: 10.2 | J19: 6.1 | K19: 6.3
A20: 온라인·디지털 | B20: 인터넷 기사 | C20: 21.3 | D20: 28.6 | E20: 31.9 | F20: 21.1 | G20: 16 | H20: 15 | I20: 17.9 | J20: 13.4 | K20: 11.8
... A37: 기업활동·후원 | B37: 회사의 사회공헌 및 기여활동 | C37: 61.8 | D37: 14.1 | E37: 12.4 | F37: 16.5 | G37: 12.3 | H37: 13.1 | I37: 9.1 | J37: 6.2 | K37: 3.9
A38: 기업활동·후원 | B38: 게임 또는 스포츠 팀 후원 | C38: 15.2 | F38: 12.9 | G38: 10.3 | I38: 5.9 | J38: 3.8
A39: 기업활동·후원 | B39: TV프로그램/영화 제작 투자 | C39: 13.9 | D39: 12.5 | E39: 12.1 | F39: 13.3 | G39: 11.4 | H39: 9 | I39: 7 | J39: 3.6 | K39: 2.5
A40: 기업활동·후원 | B40: 신제품발표회/무역박람회/전시회 | C40: 14.5 | D40: 10.4 | E40: 10.6 | F40: 13.6 | G40: 9.9 | H40: 10.1 | I40: 5.7 | J40: 4 | K40: 2.7

Sheet 2017_접점비교
A1: 2017년 접점 비교 및 순위
A2: 비율은 '통합데이터' 시트에서 자동으로 가져옴. 순위는 값이 있는 접점 중 순위(1=가장 높음). 오른쪽 '고유순위'는 TOP10 표를 만들기 위한 보조 열(동점 처리).
A4: 구분 | B4: 접점(매체) | C4: 인지(%) | D4: 호감(%) | E4: 구매(%) | F4: 3단계 평균(%) | G4: 구매÷인지(배) | H4: 구매÷호감(배) | I4: 인지 순위 | J4: 호감 순위 | K4: 구매 순위 | L4: 평균 순위 | M4: 고유순위·인지 | N4: 고유순위·호감 | O4: 고유순위·구매 | P4: 고유순위·평균
A5: =통합데이터!A7 -> TV·라디오 | B5: =통합데이터!B7 -> TV 광고 | C5: =IF(통합데이터!C7="","",통합데이터!C7) -> 77.7 | D5: =IF(통합데이터!F7="","",통합데이터!F7) -> 62.6 | E5: =IF(통합데이터!I7="","",통합데이터!I7) -> 51.6 | F5: =IF(COUNT(C5:E5)=3,AVERAGE(C5:E5),"") -> 63.966667 | G5: =IF(OR(C5="",E5=""),"",IF(C5=0,"",E5/C5)) -> 0.66409266 | H5: =IF(OR(D5="",E5=""),"",IF(D5=0,"",E5/D5)) -> 0.82428115 | I5: =IF(C5="","",RANK(C5,$C$5:$C$38)) -> 1 | J5: =IF(D5="","",RANK(D5,$D$5:$D$38)) -> 1 | K5: =IF(E5="","",RANK(E5,$E$5:$E$38)) -> 2 | L5: =IF(F5="","",RANK(F5,$F$5:$F$38)) -> 1 | M5: =IF(C5="","",RANK(C5,$C$5:$C$38)+COUNTIF($C$4:C4,C5)) -> 1 | N5: =IF(D5="","",RANK(D5,$D$5:$D$38)+COUNTIF($D$4:D4,D5)) -> 1 | O5: =IF(E5="","",RANK(E5,$E$5:$E$38)+COUNTIF($E$4:E4,E5)) -> 2 | P5: =IF(F5="","",RANK(F5,$F$5:$F$38)+COUNTIF($F$4:F4,F5)) -> 1
A6: =통합데이터!A8 -> TV·라디오 | B6: =통합데이터!B8 -> 드라마 등 TV프로그램 속 간접광고(PPL) | C6: =IF(통합데이터!C8="","",통합데이터!C8) | D6: =IF(통합데이터!F8="","",통합데이터!F8) -> 33.4 | E6: =IF(통합데이터!I8="","",통합데이터!I8) -> 20.7 | F6: =IF(COUNT(C6:E6)=3,AVERAGE(C6:E6),"") | G6: =IF(OR(C6="",E6=""),"",IF(C6=0,"",E6/C6)) | H6: =IF(OR(D6="",E6=""),"",IF(D6=0,"",E6/D6)) -> 0.61976048 | I6: =IF(C6="","",RANK(C6,$C$5:$C$38)) | J6: =IF(D6="","",RANK(D6,$D$5:$D$38)) -> 4 | K6: =IF(E6="","",RANK(E6,$E$5:$E$38)) -> 9 | L6: =IF(F6="","",RANK(F6,$F$5:$F$38)) | M6: =IF(C6="","",RANK(C6,$C$5:$C$38)+COUNTIF($C$4:C5,C6)) | N6: =IF(D6="","",RANK(D6,$D$5:$D$38)+COUNTIF($D$4:D5,D6)) -> 4 | O6: =IF(E6="","",RANK(E6,$E$5:$E$38)+COUNTIF($E$4:E5,E6)) -> 9 | P6: =IF(F6="","",RANK(F6,$F$5:$F$38)+COUNTIF($F$4:F5,F6))
A7: =통합데이터!A9 -> TV·라디오 | B7: =통합데이터!B9 -> 라디오 광고 | C7: =IF(통합데이터!C9="","",통합데이터!C9) -> 34 | D7: =IF(통합데이터!F9="","",통합데이터!F9) -> 9.5 | E7: =IF(통합데이터!I9="","",통합데이터!I9) -> 4.9 | F7: =IF(COUNT(C7:E7)=3,AVERAGE(C7:E7),"") -> 16.133333 | G7: =IF(OR(C7="",E7=""),"",IF(C7=0,"",E7/C7)) -> 0.14411765 | H7: =IF(OR(D7="",E7=""),"",IF(D7=0,"",E7/D7)) -> 0.51578947 | I7: =IF(C7="","",RANK(C7,$C$5:$C$38)) -> 10 | J7: =IF(D7="","",RANK(D7,$D$5:$D$38)) -> 34 | K7: =IF(E7="","",RANK(E7,$E$5:$E$38)) -> 34 | L7: =IF(F7="","",RANK(F7,$F$5:$F$38)) -> 21 | M7: =IF(C7="","",RANK(C7,$C$5:$C$38)+COUNTIF($C$4:C6,C7)) -> 10 | N7: =IF(D7="","",RANK(D7,$D$5:$D$38)+COUNTIF($D$4:D6,D7)) -> 34 | O7: =IF(E7="","",RANK(E7,$E$5:$E$38)+COUNTIF($E$4:E6,E7)) -> 34 | P7: =IF(F7="","",RANK(F7,$F$5:$F$38)+COUNTIF($F$4:F6,F7)) -> 21
A8: =통합데이터!A10 -> 인쇄·DM | B8: =통합데이터!B10 -> 신문 광고 | C8: =IF(통합데이터!C10="","",통합데이터!C10) -> 15.4 | D8: =IF(통합데이터!F10="","",통합데이터!F10) -> 12.9 | E8: =IF(통합데이터!I10="","",통합데이터!I10) -> 7 | F8: =IF(COUNT(C8:E8)=3,AVERAGE(C8:E8),"") -> 11.766667 | G8: =IF(OR(C8="",E8=""),"",IF(C8=0,"",E8/C8)) -> 0.45454545 | H8: =IF(OR(D8="",E8=""),"",IF(D8=0,"",E8/D8)) -> 0.54263566 | I8: =IF(C8="","",RANK(C8,$C$5:$C$38)) -> 27 | J8: =IF(D8="","",RANK(D8,$D$5:$D$38)) -> 28 | K8: =IF(E8="","",RANK(E8,$E$5:$E$38)) -> 27 | L8: =IF(F8="","",RANK(F8,$F$5:$F$38)) -> 29 | M8: =IF(C8="","",RANK(C8,$C$5:$C$38)+COUNTIF($C$4:C7,C8)) -> 27 | N8: =IF(D8="","",RANK(D8,$D$5:$D$38)+COUNTIF($D$4:D7,D8)) -> 28 | O8: =IF(E8="","",RANK(E8,$E$5:$E$38)+COUNTIF($E$4:E7,E8)) -> 27 | P8: =IF(F8="","",RANK(F8,$F$5:$F$38)+COUNTIF($F$4:F7,F8)) -> 29
A9: =통합데이터!A11 -> 인쇄·DM | B9: =통합데이터!B11 -> 신문 기사 | C9: =IF(통합데이터!C11="","",통합데이터!C11) -> 17.5 | D9: =IF(통합데이터!F11="","",통합데이터!F11) -> 11.1 | E9: =IF(통합데이터!I11="","",통합데이터!I11) -> 7.7 | F9: =IF(COUNT(C9:E9)=3,AVERAGE(C9:E9),"") -> 12.1 | G9: =IF(OR(C9="",E9=""),"",IF(C9=0,"",E9/C9)) -> 0.44 | H9: =IF(OR(D9="",E9=""),"",IF(D9=0,"",E9/D9)) -> 0.69369369 | I9: =IF(C9="","",RANK(C9,$C$5:$C$38)) -> 24 | J9: =IF(D9="","",RANK(D9,$D$5:$D$38)) -> 32 | K9: =IF(E9="","",RANK(E9,$E$5:$E$38)) -> 25 | L9: =IF(F9="","",RANK(F9,$F$5:$F$38)) -> 27 | M9: =IF(C9="","",RANK(C9,$C$5:$C$38)+COUNTIF($C$4:C8,C9)) -> 24 | N9: =IF(D9="","",RANK(D9,$D$5:$D$38)+COUNTIF($D$4:D8,D9)) -> 32 | O9: =IF(E9="","",RANK(E9,$E$5:$E$38)+COUNTIF($E$4:E8,E9)) -> 25 | P9: =IF(F9="","",RANK(F9,$F$5:$F$38)+COUNTIF($F$4:F8,F9)) -> 27
A10: =통합데이터!A12 -> 인쇄·DM | B10: =통합데이터!B12 -> 잡지 광고 | C10: =IF(통합데이터!C12="","",통합데이터!C12) -> 16.2 | D10: =IF(통합데이터!F12="","",통합데이터!F12) -> 18.7 | E10: =IF(통합데이터!I12="","",통합데이터!I12) -> 7.7 | F10: =IF(COUNT(C10:E10)=3,AVERAGE(C10:E10),"") -> 14.2 | G10: =IF(OR(C10="",E10=""),"",IF(C10=0,"",E10/C10)) -> 0.47530864 | H10: =IF(OR(D10="",E10=""),"",IF(D10=0,"",E10/D10)) -> 0.41176471 | I10: =IF(C10="","",RANK(C10,$C$5:$C$38)) -> 26 | J10: =IF(D10="","",RANK(D10,$D$5:$D$38)) -> 18 | K10: =IF(E10="","",RANK(E10,$E$5:$E$38)) -> 25 | L10: =IF(F10="","",RANK(F10,$F$5:$F$38)) -> 25 | M10: =IF(C10="","",RANK(C10,$C$5:$C$38)+COUNTIF($C$4:C9,C10)) -> 26 | N10: =IF(D10="","",RANK(D10,$D$5:$D$38)+COUNTIF($D$4:D9,D10)) -> 18 | O10: =IF(E10="","",RANK(E10,$E$5:$E$38)+COUNTIF($E$4:E9,E10)) -> 26 | P10: =IF(F10="","",RANK(F10,$F$5:$F$38)+COUNTIF($F$4:F9,F10)) -> 25
A11: =통합데이터!A13 -> 인쇄·DM | B11: =통합데이터!B13 -> 잡지 기사 | C11: =IF(통합데이터!C13="","",통합데이터!C13) -> 15.1 | D11: =IF(통합데이터!F13="","",통합데이터!F13) -> 12.4 | E11: =IF(통합데이터!I13="","",통합데이터!I13) -> 8.6 | F11: =IF(COUNT(C11:E11)=3,AVERAGE(C11:E11),"") -> 12.033333 | G11: =IF(OR(C11="",E11=""),"",IF(C11=0,"",E11/C11)) -> 0.56953642 | H11: =IF(OR(D11="",E11=""),"",IF(D11=0,"",E11/D11)) -> 0.69354839 | I11: =IF(C11="","",RANK(C11,$C$5:$C$38)) -> 29 | J11: =IF(D11="","",RANK(D11,$D$5:$D$38)) -> 30 | K11: =IF(E11="","",RANK(E11,$E$5:$E$38)) -> 23 | L11: =IF(F11="","",RANK(F11,$F$5:$F$38)) -> 28 | M11: =IF(C11="","",RANK(C11,$C$5:$C$38)+COUNTIF($C$4:C10,C11)) -> 29 | N11: =IF(D11="","",RANK(D11,$D$5:$D$38)+COUNTIF($D$4:D10,D11)) -> 30 | O11: =IF(E11="","",RANK(E11,$E$5:$E$38)+COUNTIF($E$4:E10,E11)) -> 23 | P11: =IF(F11="","",RANK(F11,$F$5:$F$38)+COUNTIF($F$4:F10,F11)) -> 28
A12: =통합데이터!A14 -> 인쇄·DM | B12: =통합데이터!B14 -> 제품 카달로그/전단지 | C12: =IF(통합데이터!C14="","",통합데이터!C14) -> 14 | D12: =IF(통합데이터!F14="","",통합데이터!F14) -> 26.7 | E12: =IF(통합데이터!I14="","",통합데이터!I14) -> 19.3 | F12: =IF(COUNT(C12:E12)=3,AVERAGE(C12:E12),"") -> 20 | G12: =IF(OR(C12="",E12=""),"",IF(C12=0,"",E12/C12)) -> 1.3785714 | H12: =IF(OR(D12="",E12=""),"",IF(D12=0,"",E12/D12)) -> 0.72284644 | I12: =IF(C12="","",RANK(C12,$C$5:$C$38)) -> 32 | J12: =IF(D12="","",RANK(D12,$D$5:$D$38)) -> 7 | K12: =IF(E12="","",RANK(E12,$E$5:$E$38)) -> 11 | L12: =IF(F12="","",RANK(F12,$F$5:$F$38)) -> 17 | M12: =IF(C12="","",RANK(C12,$C$5:$C$38)+COUNTIF($C$4:C11,C12)) -> 32 | N12: =IF(D12="","",RANK(D12,$D$5:$D$38)+COUNTIF($D$4:D11,D12)) -> 7 | O12: =IF(E12="","",RANK(E12,$E$5:$E$38)+COUNTIF($E$4:E11,E12)) -> 11 | P12: =IF(F12="","",RANK(F12,$F$5:$F$38)+COUNTIF($F$4:F11,F12)) -> 17
A13: =통합데이터!A15 -> 인쇄·DM | B13: =통합데이터!B15 -> 광고 우편물/명세서 등 | C13: =IF(통합데이터!C15="","",통합데이터!C15) -> 35.2 | D13: =IF(통합데이터!F15="","",통합데이터!F15) -> 14.2 | E13: =IF(통합데이터!I15="","",통합데이터!I15) -> 8.6 | F13: =IF(COUNT(C13:E13)=3,AVERAGE(C13:E13),"") -> 19.333333 | G13: =IF(OR(C13="",E13=""),"",IF(C13=0,"",E13/C13)) -> 0.24431818 | H13: =IF(OR(D13="",E13=""),"",IF(D13=0,"",E13/D13)) -> 0.6056338 | I13: =IF(C13="","",RANK(C13,$C$5:$C$38)) -> 7 | J13: =IF(D13="","",RANK(D13,$D$5:$D$38)) -> 24 | K13: =IF(E13="","",RANK(E13,$E$5:$E$38)) -> 23 | L13: =IF(F13="","",RANK(F13,$F$5:$F$38)) -> 18 | M13: =IF(C13="","",RANK(C13,$C$5:$C$38)+COUNTIF($C$4:C12,C13)) -> 7 | N13: =IF(D13="","",RANK(D13,$D$5:$D$38)+COUNTIF($D$4:D12,D13)) -> 24 | O13: =IF(E13="","",RANK(E13,$E$5:$E$38)+COUNTIF($E$4:E12,E13)) -> 24 | P13: =IF(F13="","",RANK(F13,$F$5:$F$38)+COUNTIF($F$4:F12,F13)) -> 18
A14: =통합데이터!A16 -> 온라인·디지털 | B14: =통합데이터!B16 -> 배너 광고 | C14: =IF(통합데이터!C16="","",통합데이터!C16) -> 24 | D14: =IF(통합데이터!F16="","",통합데이터!F16) -> 13.6 | E14: =IF(통합데이터!I16="","",통합데이터!I16) -> 6.2 | F14: =IF(COUNT(C14:E14)=3,AVERAGE(C14:E14),"") -> 14.6 | G14: =IF(OR(C14="",E14=""),"",IF(C14=0,"",E14/C14)) -> 0.25833333 | H14: =IF(OR(D14="",E14=""),"",IF(D14=0,"",E14/D14)) -> 0.45588235 | I14: =IF(C14="","",RANK(C14,$C$5:$C$38)) -> 19 | J14: =IF(D14="","",RANK(D14,$D$5:$D$38)) -> 25 | K14: =IF(E14="","",RANK(E14,$E$5:$E$38)) -> 30 | L14: =IF(F14="","",RANK(F14,$F$5:$F$38)) -> 23 | M14: =IF(C14="","",RANK(C14,$C$5:$C$38)+COUNTIF($C$4:C13,C14)) -> 19 | N14: =IF(D14="","",RANK(D14,$D$5:$D$38)+COUNTIF($D$4:D13,D14)) -> 25 | O14: =IF(E14="","",RANK(E14,$E$5:$E$38)+COUNTIF($E$4:E13,E14)) -> 30 | P14: =IF(F14="","",RANK(F14,$F$5:$F$38)+COUNTIF($F$4:F13,F14)) -> 23
A15: =통합데이터!A17 -> 온라인·디지털 | B15: =통합데이터!B17 -> 팝업 광고 | C15: =IF(통합데이터!C17="","",통합데이터!C17) -> 18.3 | D15: =IF(통합데이터!F17="","",통합데이터!F17) -> 12.4 | E15: =IF(통합데이터!I17="","",통합데이터!I17) -> 6.4 | F15: =IF(COUNT(C15:E15)=3,AVERAGE(C15:E15),"") -> 12.366667 | G15: =IF(OR(C15="",E15=""),"",IF(C15=0,"",E15/C15)) -> 0.34972678 | H15: =IF(OR(D15="",E15=""),"",IF(D15=0,"",E15/D15)) -> 0.51612903 | I15: =IF(C15="","",RANK(C15,$C$5:$C$38)) -> 23 | J15: =IF(D15="","",RANK(D15,$D$5:$D$38)) -> 30 | K15: =IF(E15="","",RANK(E15,$E$5:$E$38)) -> 29 | L15: =IF(F15="","",RANK(F15,$F$5:$F$38)) -> 26 | M15: =IF(C15="","",RANK(C15,$C$5:$C$38)+COUNTIF($C$4:C14,C15)) -> 23 | N15: =IF(D15="","",RANK(D15,$D$5:$D$38)+COUNTIF($D$4:D14,D15)) -> 31 | O15: =IF(E15="","",RANK(E15,$E$5:$E$38)+COUNTIF($E$4:E14,E15)) -> 29 | P15: =IF(F15="","",RANK(F15,$F$5:$F$38)+COUNTIF($F$4:F14,F15)) -> 26
A16: =통합데이터!A18 -> 온라인·디지털 | B16: =통합데이터!B18 -> 동영상 광고 (동영상 재생 전후 등) | C16: =IF(통합데이터!C18="","",통합데이터!C18) -> 16.6 | D16: =IF(통합데이터!F18="","",통합데이터!F18) -> 17 | E16: =IF(통합데이터!I18="","",통합데이터!I18) -> 10.2 | F16: =IF(COUNT(C16:E16)=3,AVERAGE(C16:E16),"") -> 14.6 | G16: =IF(OR(C16="",E16=""),"",IF(C16=0,"",E16/C16)) -> 0.61445783 | H16: =IF(OR(D16="",E16=""),"",IF(D16=0,"",E16/D16)) -> 0.6 | I16: =IF(C16="","",RANK(C16,$C$5:$C$38)) -> 25 | J16: =IF(D16="","",RANK(D16,$D$5:$D$38)) -> 20 | K16: =IF(E16="","",RANK(E16,$E$5:$E$38)) -> 19 | L16: =IF(F16="","",RANK(F16,$F$5:$F$38)) -> 23 | M16: =IF(C16="","",RANK(C16,$C$5:$C$38)+COUNTIF($C$4:C15,C16)) -> 25 | N16: =IF(D16="","",RANK(D16,$D$5:$D$38)+COUNTIF($D$4:D15,D16)) -> 20 | O16: =IF(E16="","",RANK(E16,$E$5:$E$38)+COUNTIF($E$4:E15,E16)) -> 19 | P16: =IF(F16="","",RANK(F16,$F$5:$F$38)+COUNTIF($F$4:F15,F16)) -> 24
... A38: =통합데이터!A40 -> 기업활동·후원 | B38: =통합데이터!B40 -> 신제품발표회/무역박람회/전시회 | C38: =IF(통합데이터!C40="","",통합데이터!C40) -> 14.5 | D38: =IF(통합데이터!F40="","",통합데이터!F40) -> 13.6 | E38: =IF(통합데이터!I40="","",통합데이터!I40) -> 5.7 | F38: =IF(COUNT(C38:E38)=3,AVERAGE(C38:E38),"") -> 11.266667 | G38: =IF(OR(C38="",E38=""),"",IF(C38=0,"",E38/C38)) -> 0.39310345 | H38: =IF(OR(D38="",E38=""),"",IF(D38=0,"",E38/D38)) -> 0.41911765 | I38: =IF(C38="","",RANK(C38,$C$5:$C$38)) -> 30 | J38: =IF(D38="","",RANK(D38,$D$5:$D$38)) -> 25 | K38: =IF(E38="","",RANK(E38,$E$5:$E$38)) -> 32 | L38: =IF(F38="","",RANK(F38,$F$5:$F$38)) -> 33 | M38: =IF(C38="","",RANK(C38,$C$5:$C$38)+COUNTIF($C$4:C37,C38)) -> 30 | N38: =IF(D38="","",RANK(D38,$D$5:$D$38)+COUNTIF($D$4:D37,D38)) -> 26 | O38: =IF(E38="","",RANK(E38,$E$5:$E$38)+COUNTIF($E$4:E37,E38)) -> 32 | P38: =IF(F38="","",RANK(F38,$F$5:$F$38)+COUNTIF($F$4:F37,F38)) -> 33
A40: 음영 = 해당 단계 상위 5위. 3단계 평균은 세 단계를 동일 비중으로 본 단순 평균(가정). 구매÷인지는 전환율이 아닌 상대 지표.

Sheet 2018_접점비교
A1: 2018년 접점 비교 및 순위
A2: 비율은 '통합데이터' 시트에서 자동으로 가져옴. 순위는 값이 있는 접점 중 순위(1=가장 높음). 오른쪽 '고유순위'는 TOP10 표를 만들기 위한 보조 열(동점 처리).
A4: 구분 | B4: 접점(매체) | C4: 인지(%) | D4: 호감(%) | E4: 구매(%) | F4: 3단계 평균(%) | G4: 구매÷인지(배) | H4: 구매÷호감(배) | I4: 인지 순위 | J4: 호감 순위 | K4: 구매 순위 | L4: 평균 순위 | M4: 고유순위·인지 | N4: 고유순위·호감 | O4: 고유순위·구매 | P4: 고유순위·평균
A5: =통합데이터!A7 -> TV·라디오 | B5: =통합데이터!B7 -> TV 광고 | C5: =IF(통합데이터!D7="","",통합데이터!D7) -> 75.8 | D5: =IF(통합데이터!G7="","",통합데이터!G7) -> 60.4 | E5: =IF(통합데이터!J7="","",통합데이터!J7) -> 43.4 | F5: =IF(COUNT(C5:E5)=3,AVERAGE(C5:E5),"") -> 59.866667 | G5: =IF(OR(C5="",E5=""),"",IF(C5=0,"",E5/C5)) -> 0.57255937 | H5: =IF(OR(D5="",E5=""),"",IF(D5=0,"",E5/D5)) -> 0.71854305 | I5: =IF(C5="","",RANK(C5,$C$5:$C$38)) -> 1 | J5: =IF(D5="","",RANK(D5,$D$5:$D$38)) -> 1 | K5: =IF(E5="","",RANK(E5,$E$5:$E$38)) -> 2 | L5: =IF(F5="","",RANK(F5,$F$5:$F$38)) -> 1 | M5: =IF(C5="","",RANK(C5,$C$5:$C$38)+COUNTIF($C$4:C4,C5)) -> 1 | N5: =IF(D5="","",RANK(D5,$D$5:$D$38)+COUNTIF($D$4:D4,D5)) -> 1 | O5: =IF(E5="","",RANK(E5,$E$5:$E$38)+COUNTIF($E$4:E4,E5)) -> 2 | P5: =IF(F5="","",RANK(F5,$F$5:$F$38)+COUNTIF($F$4:F4,F5)) -> 1
A6: =통합데이터!A8 -> TV·라디오 | B6: =통합데이터!B8 -> 드라마 등 TV프로그램 속 간접광고(PPL) | C6: =IF(통합데이터!D8="","",통합데이터!D8) -> 44.2 | D6: =IF(통합데이터!G8="","",통합데이터!G8) -> 36.3 | E6: =IF(통합데이터!J8="","",통합데이터!J8) -> 20.5 | F6: =IF(COUNT(C6:E6)=3,AVERAGE(C6:E6),"") -> 33.666667 | G6: =IF(OR(C6="",E6=""),"",IF(C6=0,"",E6/C6)) -> 0.4638009 | H6: =IF(OR(D6="",E6=""),"",IF(D6=0,"",E6/D6)) -> 0.56473829 | I6: =IF(C6="","",RANK(C6,$C$5:$C$38)) -> 3 | J6: =IF(D6="","",RANK(D6,$D$5:$D$38)) -> 3 | K6: =IF(E6="","",RANK(E6,$E$5:$E$38)) -> 8 | L6: =IF(F6="","",RANK(F6,$F$5:$F$38)) -> 5 | M6: =IF(C6="","",RANK(C6,$C$5:$C$38)+COUNTIF($C$4:C5,C6)) -> 3 | N6: =IF(D6="","",RANK(D6,$D$5:$D$38)+COUNTIF($D$4:D5,D6)) -> 3 | O6: =IF(E6="","",RANK(E6,$E$5:$E$38)+COUNTIF($E$4:E5,E6)) -> 8 | P6: =IF(F6="","",RANK(F6,$F$5:$F$38)+COUNTIF($F$4:F5,F6)) -> 5
A7: =통합데이터!A9 -> TV·라디오 | B7: =통합데이터!B9 -> 라디오 광고 | C7: =IF(통합데이터!D9="","",통합데이터!D9) -> 25.2 | D7: =IF(통합데이터!G9="","",통합데이터!G9) -> 10.4 | E7: =IF(통합데이터!J9="","",통합데이터!J9) -> 6.2 | F7: =IF(COUNT(C7:E7)=3,AVERAGE(C7:E7),"") -> 13.933333 | G7: =IF(OR(C7="",E7=""),"",IF(C7=0,"",E7/C7)) -> 0.24603175 | H7: =IF(OR(D7="",E7=""),"",IF(D7=0,"",E7/D7)) -> 0.59615385 | I7: =IF(C7="","",RANK(C7,$C$5:$C$38)) -> 18 | J7: =IF(D7="","",RANK(D7,$D$5:$D$38)) -> 25 | K7: =IF(E7="","",RANK(E7,$E$5:$E$38)) -> 21 | L7: =IF(F7="","",RANK(F7,$F$5:$F$38)) -> 20 | M7: =IF(C7="","",RANK(C7,$C$5:$C$38)+COUNTIF($C$4:C6,C7)) -> 18 | N7: =IF(D7="","",RANK(D7,$D$5:$D$38)+COUNTIF($D$4:D6,D7)) -> 25 | O7: =IF(E7="","",RANK(E7,$E$5:$E$38)+COUNTIF($E$4:E6,E7)) -> 21 | P7: =IF(F7="","",RANK(F7,$F$5:$F$38)+COUNTIF($F$4:F6,F7)) -> 20
A8: =통합데이터!A10 -> 인쇄·DM | B8: =통합데이터!B10 -> 신문 광고 | C8: =IF(통합데이터!D10="","",통합데이터!D10) -> 21.9 | D8: =IF(통합데이터!G10="","",통합데이터!G10) -> 8.3 | E8: =IF(통합데이터!J10="","",통합데이터!J10) -> 4.7 | F8: =IF(COUNT(C8:E8)=3,AVERAGE(C8:E8),"") -> 11.633333 | G8: =IF(OR(C8="",E8=""),"",IF(C8=0,"",E8/C8)) -> 0.21461187 | H8: =IF(OR(D8="",E8=""),"",IF(D8=0,"",E8/D8)) -> 0.56626506 | I8: =IF(C8="","",RANK(C8,$C$5:$C$38)) -> 22 | J8: =IF(D8="","",RANK(D8,$D$5:$D$38)) -> 30 | K8: =IF(E8="","",RANK(E8,$E$5:$E$38)) -> 28 | L8: =IF(F8="","",RANK(F8,$F$5:$F$38)) -> 26 | M8: =IF(C8="","",RANK(C8,$C$5:$C$38)+COUNTIF($C$4:C7,C8)) -> 22 | N8: =IF(D8="","",RANK(D8,$D$5:$D$38)+COUNTIF($D$4:D7,D8)) -> 30 | O8: =IF(E8="","",RANK(E8,$E$5:$E$38)+COUNTIF($E$4:E7,E8)) -> 28 | P8: =IF(F8="","",RANK(F8,$F$5:$F$38)+COUNTIF($F$4:F7,F8)) -> 26
A9: =통합데이터!A11 -> 인쇄·DM | B9: =통합데이터!B11 -> 신문 기사 | C9: =IF(통합데이터!D11="","",통합데이터!D11) -> 14.4 | D9: =IF(통합데이터!G11="","",통합데이터!G11) -> 7.4 | E9: =IF(통합데이터!J11="","",통합데이터!J11) -> 5.9 | F9: =IF(COUNT(C9:E9)=3,AVERAGE(C9:E9),"") -> 9.2333333 | G9: =IF(OR(C9="",E9=""),"",IF(C9=0,"",E9/C9)) -> 0.40972222 | H9: =IF(OR(D9="",E9=""),"",IF(D9=0,"",E9/D9)) -> 0.7972973 | I9: =IF(C9="","",RANK(C9,$C$5:$C$38)) -> 28 | J9: =IF(D9="","",RANK(D9,$D$5:$D$38)) -> 33 | K9: =IF(E9="","",RANK(E9,$E$5:$E$38)) -> 24 | L9: =IF(F9="","",RANK(F9,$F$5:$F$38)) -> 29 | M9: =IF(C9="","",RANK(C9,$C$5:$C$38)+COUNTIF($C$4:C8,C9)) -> 28 | N9: =IF(D9="","",RANK(D9,$D$5:$D$38)+COUNTIF($D$4:D8,D9)) -> 33 | O9: =IF(E9="","",RANK(E9,$E$5:$E$38)+COUNTIF($E$4:E8,E9)) -> 24 | P9: =IF(F9="","",RANK(F9,$F$5:$F$38)+COUNTIF($F$4:F8,F9)) -> 29
A10: =통합데이터!A12 -> 인쇄·DM | B10: =통합데이터!B12 -> 잡지 광고 | C10: =IF(통합데이터!D12="","",통합데이터!D12) -> 19.1 | D10: =IF(통합데이터!G12="","",통합데이터!G12) -> 13.4 | E10: =IF(통합데이터!J12="","",통합데이터!J12) -> 4.8 | F10: =IF(COUNT(C10:E10)=3,AVERAGE(C10:E10),"") -> 12.433333 | G10: =IF(OR(C10="",E10=""),"",IF(C10=0,"",E10/C10)) -> 0.2513089 | H10: =IF(OR(D10="",E10=""),"",IF(D10=0,"",E10/D10)) -> 0.35820896 | I10: =IF(C10="","",RANK(C10,$C$5:$C$38)) -> 26 | J10: =IF(D10="","",RANK(D10,$D$5:$D$38)) -> 19 | K10: =IF(E10="","",RANK(E10,$E$5:$E$38)) -> 27 | L10: =IF(F10="","",RANK(F10,$F$5:$F$38)) -> 22 | M10: =IF(C10="","",RANK(C10,$C$5:$C$38)+COUNTIF($C$4:C9,C10)) -> 26 | N10: =IF(D10="","",RANK(D10,$D$5:$D$38)+COUNTIF($D$4:D9,D10)) -> 19 | O10: =IF(E10="","",RANK(E10,$E$5:$E$38)+COUNTIF($E$4:E9,E10)) -> 27 | P10: =IF(F10="","",RANK(F10,$F$5:$F$38)+COUNTIF($F$4:F9,F10)) -> 22
A11: =통합데이터!A13 -> 인쇄·DM | B11: =통합데이터!B13 -> 잡지 기사 | C11: =IF(통합데이터!D13="","",통합데이터!D13) -> 13.8 | D11: =IF(통합데이터!G13="","",통합데이터!G13) -> 8 | E11: =IF(통합데이터!J13="","",통합데이터!J13) -> 5.6 | F11: =IF(COUNT(C11:E11)=3,AVERAGE(C11:E11),"") -> 9.1333333 | G11: =IF(OR(C11="",E11=""),"",IF(C11=0,"",E11/C11)) -> 0.4057971 | H11: =IF(OR(D11="",E11=""),"",IF(D11=0,"",E11/D11)) -> 0.7 | I11: =IF(C11="","",RANK(C11,$C$5:$C$38)) -> 31 | J11: =IF(D11="","",RANK(D11,$D$5:$D$38)) -> 32 | K11: =IF(E11="","",RANK(E11,$E$5:$E$38)) -> 25 | L11: =IF(F11="","",RANK(F11,$F$5:$F$38)) -> 31 | M11: =IF(C11="","",RANK(C11,$C$5:$C$38)+COUNTIF($C$4:C10,C11)) -> 31 | N11: =IF(D11="","",RANK(D11,$D$5:$D$38)+COUNTIF($D$4:D10,D11)) -> 32 | O11: =IF(E11="","",RANK(E11,$E$5:$E$38)+COUNTIF($E$4:E10,E11)) -> 25 | P11: =IF(F11="","",RANK(F11,$F$5:$F$38)+COUNTIF($F$4:F10,F11)) -> 31
A12: =통합데이터!A14 -> 인쇄·DM | B12: =통합데이터!B14 -> 제품 카달로그/전단지 | C12: =IF(통합데이터!D14="","",통합데이터!D14) -> 37 | D12: =IF(통합데이터!G14="","",통합데이터!G14) -> 26.1 | E12: =IF(통합데이터!J14="","",통합데이터!J14) -> 20.3 | F12: =IF(COUNT(C12:E12)=3,AVERAGE(C12:E12),"") -> 27.8 | G12: =IF(OR(C12="",E12=""),"",IF(C12=0,"",E12/C12)) -> 0.54864865 | H12: =IF(OR(D12="",E12=""),"",IF(D12=0,"",E12/D12)) -> 0.77777778 | I12: =IF(C12="","",RANK(C12,$C$5:$C$38)) -> 8 | J12: =IF(D12="","",RANK(D12,$D$5:$D$38)) -> 7 | K12: =IF(E12="","",RANK(E12,$E$5:$E$38)) -> 9 | L12: =IF(F12="","",RANK(F12,$F$5:$F$38)) -> 6 | M12: =IF(C12="","",RANK(C12,$C$5:$C$38)+COUNTIF($C$4:C11,C12)) -> 8 | N12: =IF(D12="","",RANK(D12,$D$5:$D$38)+COUNTIF($D$4:D11,D12)) -> 7 | O12: =IF(E12="","",RANK(E12,$E$5:$E$38)+COUNTIF($E$4:E11,E12)) -> 9 | P12: =IF(F12="","",RANK(F12,$F$5:$F$38)+COUNTIF($F$4:F11,F12)) -> 6
A13: =통합데이터!A15 -> 인쇄·DM | B13: =통합데이터!B15 -> 광고 우편물/명세서 등 | C13: =IF(통합데이터!D15="","",통합데이터!D15) -> 25.9 | D13: =IF(통합데이터!G15="","",통합데이터!G15) -> 13 | E13: =IF(통합데이터!J15="","",통합데이터!J15) -> 9.5 | F13: =IF(COUNT(C13:E13)=3,AVERAGE(C13:E13),"") -> 16.133333 | G13: =IF(OR(C13="",E13=""),"",IF(C13=0,"",E13/C13)) -> 0.36679537 | H13: =IF(OR(D13="",E13=""),"",IF(D13=0,"",E13/D13)) -> 0.73076923 | I13: =IF(C13="","",RANK(C13,$C$5:$C$38)) -> 15 | J13: =IF(D13="","",RANK(D13,$D$5:$D$38)) -> 20 | K13: =IF(E13="","",RANK(E13,$E$5:$E$38)) -> 16 | L13: =IF(F13="","",RANK(F13,$F$5:$F$38)) -> 19 | M13: =IF(C13="","",RANK(C13,$C$5:$C$38)+COUNTIF($C$4:C12,C13)) -> 15 | N13: =IF(D13="","",RANK(D13,$D$5:$D$38)+COUNTIF($D$4:D12,D13)) -> 20 | O13: =IF(E13="","",RANK(E13,$E$5:$E$38)+COUNTIF($E$4:E12,E13)) -> 16 | P13: =IF(F13="","",RANK(F13,$F$5:$F$38)+COUNTIF($F$4:F12,F13)) -> 19
A14: =통합데이터!A16 -> 온라인·디지털 | B14: =통합데이터!B16 -> 배너 광고 | C14: =IF(통합데이터!D16="","",통합데이터!D16) -> 23.6 | D14: =IF(통합데이터!G16="","",통합데이터!G16) -> 9 | E14: =IF(통합데이터!J16="","",통합데이터!J16) -> 4.1 | F14: =IF(COUNT(C14:E14)=3,AVERAGE(C14:E14),"") -> 12.233333 | G14: =IF(OR(C14="",E14=""),"",IF(C14=0,"",E14/C14)) -> 0.17372881 | H14: =IF(OR(D14="",E14=""),"",IF(D14=0,"",E14/D14)) -> 0.45555556 | I14: =IF(C14="","",RANK(C14,$C$5:$C$38)) -> 20 | J14: =IF(D14="","",RANK(D14,$D$5:$D$38)) -> 28 | K14: =IF(E14="","",RANK(E14,$E$5:$E$38)) -> 29 | L14: =IF(F14="","",RANK(F14,$F$5:$F$38)) -> 23 | M14: =IF(C14="","",RANK(C14,$C$5:$C$38)+COUNTIF($C$4:C13,C14)) -> 20 | N14: =IF(D14="","",RANK(D14,$D$5:$D$38)+COUNTIF($D$4:D13,D14)) -> 28 | O14: =IF(E14="","",RANK(E14,$E$5:$E$38)+COUNTIF($E$4:E13,E14)) -> 29 | P14: =IF(F14="","",RANK(F14,$F$5:$F$38)+COUNTIF($F$4:F13,F14)) -> 23
A15: =통합데이터!A17 -> 온라인·디지털 | B15: =통합데이터!B17 -> 팝업 광고 | C15: =IF(통합데이터!D17="","",통합데이터!D17) -> 21.6 | D15: =IF(통합데이터!G17="","",통합데이터!G17) -> 8.1 | E15: =IF(통합데이터!J17="","",통합데이터!J17) -> 3.4 | F15: =IF(COUNT(C15:E15)=3,AVERAGE(C15:E15),"") -> 11.033333 | G15: =IF(OR(C15="",E15=""),"",IF(C15=0,"",E15/C15)) -> 0.15740741 | H15: =IF(OR(D15="",E15=""),"",IF(D15=0,"",E15/D15)) -> 0.41975309 | I15: =IF(C15="","",RANK(C15,$C$5:$C$38)) -> 23 | J15: =IF(D15="","",RANK(D15,$D$5:$D$38)) -> 31 | K15: =IF(E15="","",RANK(E15,$E$5:$E$38)) -> 33 | L15: =IF(F15="","",RANK(F15,$F$5:$F$38)) -> 27 | M15: =IF(C15="","",RANK(C15,$C$5:$C$38)+COUNTIF($C$4:C14,C15)) -> 23 | N15: =IF(D15="","",RANK(D15,$D$5:$D$38)+COUNTIF($D$4:D14,D15)) -> 31 | O15: =IF(E15="","",RANK(E15,$E$5:$E$38)+COUNTIF($E$4:E14,E15)) -> 33 | P15: =IF(F15="","",RANK(F15,$F$5:$F$38)+COUNTIF($F$4:F14,F15)) -> 27
A16: =통합데이터!A18 -> 온라인·디지털 | B16: =통합데이터!B18 -> 동영상 광고 (동영상 재생 전후 등) | C16: =IF(통합데이터!D18="","",통합데이터!D18) -> 23.4 | D16: =IF(통합데이터!G18="","",통합데이터!G18) -> 12.2 | E16: =IF(통합데이터!J18="","",통합데이터!J18) -> 5.3 | F16: =IF(COUNT(C16:E16)=3,AVERAGE(C16:E16),"") -> 13.633333 | G16: =IF(OR(C16="",E16=""),"",IF(C16=0,"",E16/C16)) -> 0.22649573 | H16: =IF(OR(D16="",E16=""),"",IF(D16=0,"",E16/D16)) -> 0.43442623 | I16: =IF(C16="","",RANK(C16,$C$5:$C$38)) -> 21 | J16: =IF(D16="","",RANK(D16,$D$5:$D$38)) -> 22 | K16: =IF(E16="","",RANK(E16,$E$5:$E$38)) -> 26 | L16: =IF(F16="","",RANK(F16,$F$5:$F$38)) -> 21 | M16: =IF(C16="","",RANK(C16,$C$5:$C$38)+COUNTIF($C$4:C15,C16)) -> 21 | N16: =IF(D16="","",RANK(D16,$D$5:$D$38)+COUNTIF($D$4:D15,D16)) -> 22 | O16: =IF(E16="","",RANK(E16,$E$5:$E$38)+COUNTIF($E$4:E15,E16)) -> 26 | P16: =IF(F16="","",RANK(F16,$F$5:$F$38)+COUNTIF($F$4:F15,F16)) -> 21
... A38: =통합데이터!A40 -> 기업활동·후원 | B38: =통합데이터!B40 -> 신제품발표회/무역박람회/전시회 | C38: =IF(통합데이터!D40="","",통합데이터!D40) -> 10.4 | D38: =IF(통합데이터!G40="","",통합데이터!G40) -> 9.9 | E38: =IF(통합데이터!J40="","",통합데이터!J40) -> 4 | F38: =IF(COUNT(C38:E38)=3,AVERAGE(C38:E38),"") -> 8.1 | G38: =IF(OR(C38="",E38=""),"",IF(C38=0,"",E38/C38)) -> 0.38461538 | H38: =IF(OR(D38="",E38=""),"",IF(D38=0,"",E38/D38)) -> 0.4040404 | I38: =IF(C38="","",RANK(C38,$C$5:$C$38)) -> 33 | J38: =IF(D38="","",RANK(D38,$D$5:$D$38)) -> 27 | K38: =IF(E38="","",RANK(E38,$E$5:$E$38)) -> 30 | L38: =IF(F38="","",RANK(F38,$F$5:$F$38)) -> 32 | M38: =IF(C38="","",RANK(C38,$C$5:$C$38)+COUNTIF($C$4:C37,C38)) -> 33 | N38: =IF(D38="","",RANK(D38,$D$5:$D$38)+COUNTIF($D$4:D37,D38)) -> 27 | O38: =IF(E38="","",RANK(E38,$E$5:$E$38)+COUNTIF($E$4:E37,E38)) -> 30 | P38: =IF(F38="","",RANK(F38,$F$5:$F$38)+COUNTIF($F$4:F37,F38)) -> 32
A40: 음영 = 해당 단계 상위 5위. 3단계 평균은 세 단계를 동일 비중으로 본 단순 평균(가정). 구매÷인지는 전환율이 아닌 상대 지표.

Sheet 2019_접점비교
A1: 2019년 접점 비교 및 순위
A2: 비율은 '통합데이터' 시트에서 자동으로 가져옴. 순위는 값이 있는 접점 중 순위(1=가장 높음). 오른쪽 '고유순위'는 TOP10 표를 만들기 위한 보조 열(동점 처리).
A4: 구분 | B4: 접점(매체) | C4: 인지(%) | D4: 호감(%) | E4: 구매(%) | F4: 3단계 평균(%) | G4: 구매÷인지(배) | H4: 구매÷호감(배) | I4: 인지 순위 | J4: 호감 순위 | K4: 구매 순위 | L4: 평균 순위 | M4: 고유순위·인지 | N4: 고유순위·호감 | O4: 고유순위·구매 | P4: 고유순위·평균
A5: =통합데이터!A7 -> TV·라디오 | B5: =통합데이터!B7 -> TV 광고 | C5: =IF(통합데이터!E7="","",통합데이터!E7) -> 82.3 | D5: =IF(통합데이터!H7="","",통합데이터!H7) -> 58.4 | E5: =IF(통합데이터!K7="","",통합데이터!K7) -> 47.1 | F5: =IF(COUNT(C5:E5)=3,AVERAGE(C5:E5),"") -> 62.6 | G5: =IF(OR(C5="",E5=""),"",IF(C5=0,"",E5/C5)) -> 0.57229648 | H5: =IF(OR(D5="",E5=""),"",IF(D5=0,"",E5/D5)) -> 0.80650685 | I5: =IF(C5="","",RANK(C5,$C$5:$C$38)) -> 1 | J5: =IF(D5="","",RANK(D5,$D$5:$D$38)) -> 1 | K5: =IF(E5="","",RANK(E5,$E$5:$E$38)) -> 2 | L5: =IF(F5="","",RANK(F5,$F$5:$F$38)) -> 1 | M5: =IF(C5="","",RANK(C5,$C$5:$C$38)+COUNTIF($C$4:C4,C5)) -> 1 | N5: =IF(D5="","",RANK(D5,$D$5:$D$38)+COUNTIF($D$4:D4,D5)) -> 1 | O5: =IF(E5="","",RANK(E5,$E$5:$E$38)+COUNTIF($E$4:E4,E5)) -> 2 | P5: =IF(F5="","",RANK(F5,$F$5:$F$38)+COUNTIF($F$4:F4,F5)) -> 1
A6: =통합데이터!A8 -> TV·라디오 | B6: =통합데이터!B8 -> 드라마 등 TV프로그램 속 간접광고(PPL) | C6: =IF(통합데이터!E8="","",통합데이터!E8) -> 42.4 | D6: =IF(통합데이터!H8="","",통합데이터!H8) -> 34.8 | E6: =IF(통합데이터!K8="","",통합데이터!K8) -> 17.1 | F6: =IF(COUNT(C6:E6)=3,AVERAGE(C6:E6),"") -> 31.433333 | G6: =IF(OR(C6="",E6=""),"",IF(C6=0,"",E6/C6)) -> 0.40330189 | H6: =IF(OR(D6="",E6=""),"",IF(D6=0,"",E6/D6)) -> 0.49137931 | I6: =IF(C6="","",RANK(C6,$C$5:$C$38)) -> 7 | J6: =IF(D6="","",RANK(D6,$D$5:$D$38)) -> 4 | K6: =IF(E6="","",RANK(E6,$E$5:$E$38)) -> 11 | L6: =IF(F6="","",RANK(F6,$F$5:$F$38)) -> 5 | M6: =IF(C6="","",RANK(C6,$C$5:$C$38)+COUNTIF($C$4:C5,C6)) -> 7 | N6: =IF(D6="","",RANK(D6,$D$5:$D$38)+COUNTIF($D$4:D5,D6)) -> 4 | O6: =IF(E6="","",RANK(E6,$E$5:$E$38)+COUNTIF($E$4:E5,E6)) -> 11 | P6: =IF(F6="","",RANK(F6,$F$5:$F$38)+COUNTIF($F$4:F5,F6)) -> 5
A7: =통합데이터!A9 -> TV·라디오 | B7: =통합데이터!B9 -> 라디오 광고 | C7: =IF(통합데이터!E9="","",통합데이터!E9) -> 25.7 | D7: =IF(통합데이터!H9="","",통합데이터!H9) -> 10.1 | E7: =IF(통합데이터!K9="","",통합데이터!K9) -> 6.1 | F7: =IF(COUNT(C7:E7)=3,AVERAGE(C7:E7),"") -> 13.966667 | G7: =IF(OR(C7="",E7=""),"",IF(C7=0,"",E7/C7)) -> 0.23735409 | H7: =IF(OR(D7="",E7=""),"",IF(D7=0,"",E7/D7)) -> 0.6039604 | I7: =IF(C7="","",RANK(C7,$C$5:$C$38)) -> 18 | J7: =IF(D7="","",RANK(D7,$D$5:$D$38)) -> 24 | K7: =IF(E7="","",RANK(E7,$E$5:$E$38)) -> 22 | L7: =IF(F7="","",RANK(F7,$F$5:$F$38)) -> 21 | M7: =IF(C7="","",RANK(C7,$C$5:$C$38)+COUNTIF($C$4:C6,C7)) -> 18 | N7: =IF(D7="","",RANK(D7,$D$5:$D$38)+COUNTIF($D$4:D6,D7)) -> 24 | O7: =IF(E7="","",RANK(E7,$E$5:$E$38)+COUNTIF($E$4:E6,E7)) -> 22 | P7: =IF(F7="","",RANK(F7,$F$5:$F$38)+COUNTIF($F$4:F6,F7)) -> 21
A8: =통합데이터!A10 -> 인쇄·DM | B8: =통합데이터!B10 -> 신문 광고 | C8: =IF(통합데이터!E10="","",통합데이터!E10) -> 18.3 | D8: =IF(통합데이터!H10="","",통합데이터!H10) -> 7.3 | E8: =IF(통합데이터!K10="","",통합데이터!K10) -> 4 | F8: =IF(COUNT(C8:E8)=3,AVERAGE(C8:E8),"") -> 9.8666667 | G8: =IF(OR(C8="",E8=""),"",IF(C8=0,"",E8/C8)) -> 0.21857923 | H8: =IF(OR(D8="",E8=""),"",IF(D8=0,"",E8/D8)) -> 0.54794521 | I8: =IF(C8="","",RANK(C8,$C$5:$C$38)) -> 25 | J8: =IF(D8="","",RANK(D8,$D$5:$D$38)) -> 30 | K8: =IF(E8="","",RANK(E8,$E$5:$E$38)) -> 27 | L8: =IF(F8="","",RANK(F8,$F$5:$F$38)) -> 27 | M8: =IF(C8="","",RANK(C8,$C$5:$C$38)+COUNTIF($C$4:C7,C8)) -> 25 | N8: =IF(D8="","",RANK(D8,$D$5:$D$38)+COUNTIF($D$4:D7,D8)) -> 30 | O8: =IF(E8="","",RANK(E8,$E$5:$E$38)+COUNTIF($E$4:E7,E8)) -> 27 | P8: =IF(F8="","",RANK(F8,$F$5:$F$38)+COUNTIF($F$4:F7,F8)) -> 27
A9: =통합데이터!A11 -> 인쇄·DM | B9: =통합데이터!B11 -> 신문 기사 | C9: =IF(통합데이터!E11="","",통합데이터!E11) -> 13 | D9: =IF(통합데이터!H11="","",통합데이터!H11) -> 6.8 | E9: =IF(통합데이터!K11="","",통합데이터!K11) -> 4.2 | F9: =IF(COUNT(C9:E9)=3,AVERAGE(C9:E9),"") -> 8 | G9: =IF(OR(C9="",E9=""),"",IF(C9=0,"",E9/C9)) -> 0.32307692 | H9: =IF(OR(D9="",E9=""),"",IF(D9=0,"",E9/D9)) -> 0.61764706 | I9: =IF(C9="","",RANK(C9,$C$5:$C$38)) -> 28 | J9: =IF(D9="","",RANK(D9,$D$5:$D$38)) -> 32 | K9: =IF(E9="","",RANK(E9,$E$5:$E$38)) -> 26 | L9: =IF(F9="","",RANK(F9,$F$5:$F$38)) -> 30 | M9: =IF(C9="","",RANK(C9,$C$5:$C$38)+COUNTIF($C$4:C8,C9)) -> 28 | N9: =IF(D9="","",RANK(D9,$D$5:$D$38)+COUNTIF($D$4:D8,D9)) -> 32 | O9: =IF(E9="","",RANK(E9,$E$5:$E$38)+COUNTIF($E$4:E8,E9)) -> 26 | P9: =IF(F9="","",RANK(F9,$F$5:$F$38)+COUNTIF($F$4:F8,F9)) -> 30
A10: =통합데이터!A12 -> 인쇄·DM | B10: =통합데이터!B12 -> 잡지 광고 | C10: =IF(통합데이터!E12="","",통합데이터!E12) -> 16.6 | D10: =IF(통합데이터!H12="","",통합데이터!H12) -> 14.4 | E10: =IF(통합데이터!K12="","",통합데이터!K12) -> 5 | F10: =IF(COUNT(C10:E10)=3,AVERAGE(C10:E10),"") -> 12 | G10: =IF(OR(C10="",E10=""),"",IF(C10=0,"",E10/C10)) -> 0.30120482 | H10: =IF(OR(D10="",E10=""),"",IF(D10=0,"",E10/D10)) -> 0.34722222 | I10: =IF(C10="","",RANK(C10,$C$5:$C$38)) -> 26 | J10: =IF(D10="","",RANK(D10,$D$5:$D$38)) -> 19 | K10: =IF(E10="","",RANK(E10,$E$5:$E$38)) -> 24 | L10: =IF(F10="","",RANK(F10,$F$5:$F$38)) -> 24 | M10: =IF(C10="","",RANK(C10,$C$5:$C$38)+COUNTIF($C$4:C9,C10)) -> 26 | N10: =IF(D10="","",RANK(D10,$D$5:$D$38)+COUNTIF($D$4:D9,D10)) -> 19 | O10: =IF(E10="","",RANK(E10,$E$5:$E$38)+COUNTIF($E$4:E9,E10)) -> 24 | P10: =IF(F10="","",RANK(F10,$F$5:$F$38)+COUNTIF($F$4:F9,F10)) -> 24
A11: =통합데이터!A13 -> 인쇄·DM | B11: =통합데이터!B13 -> 잡지 기사 | C11: =IF(통합데이터!E13="","",통합데이터!E13) -> 11 | D11: =IF(통합데이터!H13="","",통합데이터!H13) -> 8.8 | E11: =IF(통합데이터!K13="","",통합데이터!K13) -> 4.7 | F11: =IF(COUNT(C11:E11)=3,AVERAGE(C11:E11),"") -> 8.1666667 | G11: =IF(OR(C11="",E11=""),"",IF(C11=0,"",E11/C11)) -> 0.42727273 | H11: =IF(OR(D11="",E11=""),"",IF(D11=0,"",E11/D11)) -> 0.53409091 | I11: =IF(C11="","",RANK(C11,$C$5:$C$38)) -> 32 | J11: =IF(D11="","",RANK(D11,$D$5:$D$38)) -> 27 | K11: =IF(E11="","",RANK(E11,$E$5:$E$38)) -> 25 | L11: =IF(F11="","",RANK(F11,$F$5:$F$38)) -> 29 | M11: =IF(C11="","",RANK(C11,$C$5:$C$38)+COUNTIF($C$4:C10,C11)) -> 32 | N11: =IF(D11="","",RANK(D11,$D$5:$D$38)+COUNTIF($D$4:D10,D11)) -> 27 | O11: =IF(E11="","",RANK(E11,$E$5:$E$38)+COUNTIF($E$4:E10,E11)) -> 25 | P11: =IF(F11="","",RANK(F11,$F$5:$F$38)+COUNTIF($F$4:F10,F11)) -> 29
A12: =통합데이터!A14 -> 인쇄·DM | B12: =통합데이터!B14 -> 제품 카달로그/전단지 | C12: =IF(통합데이터!E14="","",통합데이터!E14) -> 41.5 | D12: =IF(통합데이터!H14="","",통합데이터!H14) -> 26.7 | E12: =IF(통합데이터!K14="","",통합데이터!K14) -> 19.6 | F12: =IF(COUNT(C12:E12)=3,AVERAGE(C12:E12),"") -> 29.266667 | G12: =IF(OR(C12="",E12=""),"",IF(C12=0,"",E12/C12)) -> 0.47228916 | H12: =IF(OR(D12="",E12=""),"",IF(D12=0,"",E12/D12)) -> 0.7340824 | I12: =IF(C12="","",RANK(C12,$C$5:$C$38)) -> 8 | J12: =IF(D12="","",RANK(D12,$D$5:$D$38)) -> 8 | K12: =IF(E12="","",RANK(E12,$E$5:$E$38)) -> 9 | L12: =IF(F12="","",RANK(F12,$F$5:$F$38)) -> 8 | M12: =IF(C12="","",RANK(C12,$C$5:$C$38)+COUNTIF($C$4:C11,C12)) -> 8 | N12: =IF(D12="","",RANK(D12,$D$5:$D$38)+COUNTIF($D$4:D11,D12)) -> 8 | O12: =IF(E12="","",RANK(E12,$E$5:$E$38)+COUNTIF($E$4:E11,E12)) -> 9 | P12: =IF(F12="","",RANK(F12,$F$5:$F$38)+COUNTIF($F$4:F11,F12)) -> 8
A13: =통합데이터!A15 -> 인쇄·DM | B13: =통합데이터!B15 -> 광고 우편물/명세서 등 | C13: =IF(통합데이터!E15="","",통합데이터!E15) -> 26.9 | D13: =IF(통합데이터!H15="","",통합데이터!H15) -> 11.6 | E13: =IF(통합데이터!K15="","",통합데이터!K15) -> 7.7 | F13: =IF(COUNT(C13:E13)=3,AVERAGE(C13:E13),"") -> 15.4 | G13: =IF(OR(C13="",E13=""),"",IF(C13=0,"",E13/C13)) -> 0.28624535 | H13: =IF(OR(D13="",E13=""),"",IF(D13=0,"",E13/D13)) -> 0.6637931 | I13: =IF(C13="","",RANK(C13,$C$5:$C$38)) -> 17 | J13: =IF(D13="","",RANK(D13,$D$5:$D$38)) -> 23 | K13: =IF(E13="","",RANK(E13,$E$5:$E$38)) -> 17 | L13: =IF(F13="","",RANK(F13,$F$5:$F$38)) -> 19 | M13: =IF(C13="","",RANK(C13,$C$5:$C$38)+COUNTIF($C$4:C12,C13)) -> 17 | N13: =IF(D13="","",RANK(D13,$D$5:$D$38)+COUNTIF($D$4:D12,D13)) -> 23 | O13: =IF(E13="","",RANK(E13,$E$5:$E$38)+COUNTIF($E$4:E12,E13)) -> 17 | P13: =IF(F13="","",RANK(F13,$F$5:$F$38)+COUNTIF($F$4:F12,F13)) -> 19
A14: =통합데이터!A16 -> 온라인·디지털 | B14: =통합데이터!B16 -> 배너 광고 | C14: =IF(통합데이터!E16="","",통합데이터!E16) -> 23.5 | D14: =IF(통합데이터!H16="","",통합데이터!H16) -> 7.7 | E14: =IF(통합데이터!K16="","",통합데이터!K16) -> 3.5 | F14: =IF(COUNT(C14:E14)=3,AVERAGE(C14:E14),"") -> 11.566667 | G14: =IF(OR(C14="",E14=""),"",IF(C14=0,"",E14/C14)) -> 0.14893617 | H14: =IF(OR(D14="",E14=""),"",IF(D14=0,"",E14/D14)) -> 0.45454545 | I14: =IF(C14="","",RANK(C14,$C$5:$C$38)) -> 20 | J14: =IF(D14="","",RANK(D14,$D$5:$D$38)) -> 29 | K14: =IF(E14="","",RANK(E14,$E$5:$E$38)) -> 29 | L14: =IF(F14="","",RANK(F14,$F$5:$F$38)) -> 25 | M14: =IF(C14="","",RANK(C14,$C$5:$C$38)+COUNTIF($C$4:C13,C14)) -> 20 | N14: =IF(D14="","",RANK(D14,$D$5:$D$38)+COUNTIF($D$4:D13,D14)) -> 29 | O14: =IF(E14="","",RANK(E14,$E$5:$E$38)+COUNTIF($E$4:E13,E14)) -> 29 | P14: =IF(F14="","",RANK(F14,$F$5:$F$38)+COUNTIF($F$4:F13,F14)) -> 25
A15: =통합데이터!A17 -> 온라인·디지털 | B15: =통합데이터!B17 -> 팝업 광고 | C15: =IF(통합데이터!E17="","",통합데이터!E17) -> 20.4 | D15: =IF(통합데이터!H17="","",통합데이터!H17) -> 7.1 | E15: =IF(통합데이터!K17="","",통합데이터!K17) -> 3 | F15: =IF(COUNT(C15:E15)=3,AVERAGE(C15:E15),"") -> 10.166667 | G15: =IF(OR(C15="",E15=""),"",IF(C15=0,"",E15/C15)) -> 0.14705882 | H15: =IF(OR(D15="",E15=""),"",IF(D15=0,"",E15/D15)) -> 0.42253521 | I15: =IF(C15="","",RANK(C15,$C$5:$C$38)) -> 24 | J15: =IF(D15="","",RANK(D15,$D$5:$D$38)) -> 31 | K15: =IF(E15="","",RANK(E15,$E$5:$E$38)) -> 30 | L15: =IF(F15="","",RANK(F15,$F$5:$F$38)) -> 26 | M15: =IF(C15="","",RANK(C15,$C$5:$C$38)+COUNTIF($C$4:C14,C15)) -> 24 | N15: =IF(D15="","",RANK(D15,$D$5:$D$38)+COUNTIF($D$4:D14,D15)) -> 31 | O15: =IF(E15="","",RANK(E15,$E$5:$E$38)+COUNTIF($E$4:E14,E15)) -> 30 | P15: =IF(F15="","",RANK(F15,$F$5:$F$38)+COUNTIF($F$4:F14,F15)) -> 26
A16: =통합데이터!A18 -> 온라인·디지털 | B16: =통합데이터!B18 -> 동영상 광고 (동영상 재생 전후 등) | C16: =IF(통합데이터!E18="","",통합데이터!E18) -> 23.5 | D16: =IF(통합데이터!H18="","",통합데이터!H18) -> 13.4 | E16: =IF(통합데이터!K18="","",통합데이터!K18) -> 6 | F16: =IF(COUNT(C16:E16)=3,AVERAGE(C16:E16),"") -> 14.3 | G16: =IF(OR(C16="",E16=""),"",IF(C16=0,"",E16/C16)) -> 0.25531915 | H16: =IF(OR(D16="",E16=""),"",IF(D16=0,"",E16/D16)) -> 0.44776119 | I16: =IF(C16="","",RANK(C16,$C$5:$C$38)) -> 20 | J16: =IF(D16="","",RANK(D16,$D$5:$D$38)) -> 20 | K16: =IF(E16="","",RANK(E16,$E$5:$E$38)) -> 23 | L16: =IF(F16="","",RANK(F16,$F$5:$F$38)) -> 20 | M16: =IF(C16="","",RANK(C16,$C$5:$C$38)+COUNTIF($C$4:C15,C16)) -> 21 | N16: =IF(D16="","",RANK(D16,$D$5:$D$38)+COUNTIF($D$4:D15,D16)) -> 20 | O16: =IF(E16="","",RANK(E16,$E$5:$E$38)+COUNTIF($E$4:E15,E16)) -> 23 | P16: =IF(F16="","",RANK(F16,$F$5:$F$38)+COUNTIF($F$4:F15,F16)) -> 20
... A38: =통합데이터!A40 -> 기업활동·후원 | B38: =통합데이터!B40 -> 신제품발표회/무역박람회/전시회 | C38: =IF(통합데이터!E40="","",통합데이터!E40) -> 10.6 | D38: =IF(통합데이터!H40="","",통합데이터!H40) -> 10.1 | E38: =IF(통합데이터!K40="","",통합데이터!K40) -> 2.7 | F38: =IF(COUNT(C38:E38)=3,AVERAGE(C38:E38),"") -> 7.8 | G38: =IF(OR(C38="",E38=""),"",IF(C38=0,"",E38/C38)) -> 0.25471698 | H38: =IF(OR(D38="",E38=""),"",IF(D38=0,"",E38/D38)) -> 0.26732673 | I38: =IF(C38="","",RANK(C38,$C$5:$C$38)) -> 33 | J38: =IF(D38="","",RANK(D38,$D$5:$D$38)) -> 24 | K38: =IF(E38="","",RANK(E38,$E$5:$E$38)) -> 31 | L38: =IF(F38="","",RANK(F38,$F$5:$F$38)) -> 32 | M38: =IF(C38="","",RANK(C38,$C$5:$C$38)+COUNTIF($C$4:C37,C38)) -> 33 | N38: =IF(D38="","",RANK(D38,$D$5:$D$38)+COUNTIF($D$4:D37,D38)) -> 25 | O38: =IF(E38="","",RANK(E38,$E$5:$E$38)+COUNTIF($E$4:E37,E38)) -> 31 | P38: =IF(F38="","",RANK(F38,$F$5:$F$38)+COUNTIF($F$4:F37,F38)) -> 32
A40: 음영 = 해당 단계 상위 5위. 3단계 평균은 세 단계를 동일 비중으로 본 단순 평균(가정). 구매÷인지는 전환율이 아닌 상대 지표.

Sheet TOP10_요약
A1: 연도별 단계별 상위 10개 접점
A2: 각 연도 '접점비교' 시트의 고유순위로 자동 정렬됨. 값이 바뀌면 순위표도 바뀐다.
A4: 2017년
A5: 인지 | E5: 호감 | I5: 구매 | M5: 3단계 평균
A6: 순위 | B6: 접점 | C6: 비율(%) | E6: 순위 | F6: 접점 | G6: 비율(%) | I6: 순위 | J6: 접점 | K6: 비율(%) | M6: 순위 | N6: 접점 | O6: 비율(%)
A7: 1 | B7: =INDEX(2017_접점비교!$B$5:$B$38,MATCH(A7,2017_접점비교!$M$5:$M$38,0)) -> TV 광고 | C7: =INDEX(2017_접점비교!$C$5:$C$38,MATCH(A7,2017_접점비교!$M$5:$M$38,0)) -> 77.7 | E7: 1 | F7: =INDEX(2017_접점비교!$B$5:$B$38,MATCH(E7,2017_접점비교!$N$5:$N$38,0)) -> TV 광고 | G7: =INDEX(2017_접점비교!$D$5:$D$38,MATCH(E7,2017_접점비교!$N$5:$N$38,0)) -> 62.6 | I7: 1 | J7: =INDEX(2017_접점비교!$B$5:$B$38,MATCH(I7,2017_접점비교!$O$5:$O$38,0)) -> 주변사람(친구/가족/동료)의 추천 | K7: =INDEX(2017_접점비교!$E$5:$E$38,MATCH(I7,2017_접점비교!$O$5:$O$38,0)) -> 62 | M7: 1 | N7: =INDEX(2017_접점비교!$B$5:$B$38,MATCH(M7,2017_접점비교!$P$5:$P$38,0)) -> TV 광고 | O7: =INDEX(2017_접점비교!$F$5:$F$38,MATCH(M7,2017_접점비교!$P$5:$P$38,0)) -> 63.966667
A8: 2 | B8: =INDEX(2017_접점비교!$B$5:$B$38,MATCH(A8,2017_접점비교!$M$5:$M$38,0)) -> 회사의 사회공헌 및 기여활동 | C8: =INDEX(2017_접점비교!$C$5:$C$38,MATCH(A8,2017_접점비교!$M$5:$M$38,0)) -> 61.8 | E8: 2 | F8: =INDEX(2017_접점비교!$B$5:$B$38,MATCH(E8,2017_접점비교!$N$5:$N$38,0)) -> 주변사람(친구/가족/동료)의 추천 | G8: =INDEX(2017_접점비교!$D$5:$D$38,MATCH(E8,2017_접점비교!$N$5:$N$38,0)) -> 44.7 | I8: 2 | J8: =INDEX(2017_접점비교!$B$5:$B$38,MATCH(I8,2017_접점비교!$O$5:$O$38,0)) -> TV 광고 | K8: =INDEX(2017_접점비교!$E$5:$E$38,MATCH(I8,2017_접점비교!$O$5:$O$38,0)) -> 51.6 | M8: 2 | N8: =INDEX(2017_접점비교!$B$5:$B$38,MATCH(M8,2017_접점비교!$P$5:$P$38,0)) -> 주변사람(친구/가족/동료)의 추천 | O8: =INDEX(2017_접점비교!$F$5:$F$38,MATCH(M8,2017_접점비교!$P$5:$P$38,0)) -> 51.266667
A9: 3 | B9: =INDEX(2017_접점비교!$B$5:$B$38,MATCH(A9,2017_접점비교!$M$5:$M$38,0)) -> 주변사람(친구/가족/동료)의 추천 | C9: =INDEX(2017_접점비교!$C$5:$C$38,MATCH(A9,2017_접점비교!$M$5:$M$38,0)) -> 47.1 | E9: 3 | F9: =INDEX(2017_접점비교!$B$5:$B$38,MATCH(E9,2017_접점비교!$N$5:$N$38,0)) -> 매장 내 진열제품 및 제품정보 | G9: =INDEX(2017_접점비교!$D$5:$D$38,MATCH(E9,2017_접점비교!$N$5:$N$38,0)) -> 35.5 | I9: 3 | J9: =INDEX(2017_접점비교!$B$5:$B$38,MATCH(I9,2017_접점비교!$O$5:$O$38,0)) -> 판매원(점원) 추천 | K9: =INDEX(2017_접점비교!$E$5:$E$38,MATCH(I9,2017_접점비교!$O$5:$O$38,0)) -> 41.5 | M9: 3 | N9: =INDEX(2017_접점비교!$B$5:$B$38,MATCH(M9,2017_접점비교!$P$5:$P$38,0)) -> 샘플/구매 사은품 | O9: =INDEX(2017_접점비교!$F$5:$F$38,MATCH(M9,2017_접점비교!$P$5:$P$38,0)) -> 36.1
A10: 4 | B10: =INDEX(2017_접점비교!$B$5:$B$38,MATCH(A10,2017_접점비교!$M$5:$M$38,0)) -> 샘플/구매 사은품 | C10: =INDEX(2017_접점비교!$C$5:$C$38,MATCH(A10,2017_접점비교!$M$5:$M$38,0)) -> 46.5 | E10: 4 | F10: =INDEX(2017_접점비교!$B$5:$B$38,MATCH(E10,2017_접점비교!$N$5:$N$38,0)) -> 드라마 등 TV프로그램 속 간접광고(PPL) | G10: =INDEX(2017_접점비교!$D$5:$D$38,MATCH(E10,2017_접점비교!$N$5:$N$38,0)) -> 33.4 | I10: 4 | J10: =INDEX(2017_접점비교!$B$5:$B$38,MATCH(I10,2017_접점비교!$O$5:$O$38,0)) -> 매장 내 진열제품 및 제품정보 | K10: =INDEX(2017_접점비교!$E$5:$E$38,MATCH(I10,2017_접점비교!$O$5:$O$38,0)) -> 37.5 | M10: 4 | N10: =INDEX(2017_접점비교!$B$5:$B$38,MATCH(M10,2017_접점비교!$P$5:$P$38,0)) -> 판매원(점원) 추천 | O10: =INDEX(2017_접점비교!$F$5:$F$38,MATCH(M10,2017_접점비교!$P$5:$P$38,0)) -> 34.8
A11: 5 | B11: =INDEX(2017_접점비교!$B$5:$B$38,MATCH(A11,2017_접점비교!$M$5:$M$38,0)) -> 쿠폰/프로모션 등 행사 및 이벤트 | C11: =INDEX(2017_접점비교!$C$5:$C$38,MATCH(A11,2017_접점비교!$M$5:$M$38,0)) -> 36.8 | E11: 5 | F11: =INDEX(2017_접점비교!$B$5:$B$38,MATCH(E11,2017_접점비교!$N$5:$N$38,0)) -> 판매원(점원) 추천 | G11: =INDEX(2017_접점비교!$D$5:$D$38,MATCH(E11,2017_접점비교!$N$5:$N$38,0)) -> 29.9 | I11: 5 | J11: =INDEX(2017_접점비교!$B$5:$B$38,MATCH(I11,2017_접점비교!$O$5:$O$38,0)) -> 샘플/구매 사은품 | K11: =INDEX(2017_접점비교!$E$5:$E$38,MATCH(I11,2017_접점비교!$O$5:$O$38,0)) -> 34 | M11: 5 | N11: =INDEX(2017_접점비교!$B$5:$B$38,MATCH(M11,2017_접점비교!$P$5:$P$38,0)) -> 매장 내 진열제품 및 제품정보 | O11: =INDEX(2017_접점비교!$F$5:$F$38,MATCH(M11,2017_접점비교!$P$5:$P$38,0)) -> 34.6
A12: 6 | B12: =INDEX(2017_접점비교!$B$5:$B$38,MATCH(A12,2017_접점비교!$M$5:$M$38,0)) -> 매장 내 광고(POP) | C12: =INDEX(2017_접점비교!$C$5:$C$38,MATCH(A12,2017_접점비교!$M$5:$M$38,0)) -> 35.6 | E12: 6 | F12: =INDEX(2017_접점비교!$B$5:$B$38,MATCH(E12,2017_접점비교!$N$5:$N$38,0)) -> 샘플/구매 사은품 | G12: =INDEX(2017_접점비교!$D$5:$D$38,MATCH(E12,2017_접점비교!$N$5:$N$38,0)) -> 27.8 | I12: 6 | J12: =INDEX(2017_접점비교!$B$5:$B$38,MATCH(I12,2017_접점비교!$O$5:$O$38,0)) -> 쿠폰/프로모션 등 행사 및 이벤트 | K12: =INDEX(2017_접점비교!$E$5:$E$38,MATCH(I12,2017_접점비교!$O$5:$O$38,0)) -> 29.3 | M12: 6 | N12: =INDEX(2017_접점비교!$B$5:$B$38,MATCH(M12,2017_접점비교!$P$5:$P$38,0)) -> 쿠폰/프로모션 등 행사 및 이벤트 | O12: =INDEX(2017_접점비교!$F$5:$F$38,MATCH(M12,2017_접점비교!$P$5:$P$38,0)) -> 30.8
A13: 7 | B13: =INDEX(2017_접점비교!$B$5:$B$38,MATCH(A13,2017_접점비교!$M$5:$M$38,0)) -> 광고 우편물/명세서 등 | C13: =INDEX(2017_접점비교!$C$5:$C$38,MATCH(A13,2017_접점비교!$M$5:$M$38,0)) -> 35.2 | E13: 7 | F13: =INDEX(2017_접점비교!$B$5:$B$38,MATCH(E13,2017_접점비교!$N$5:$N$38,0)) -> 제품 카달로그/전단지 | G13: =INDEX(2017_접점비교!$D$5:$D$38,MATCH(E13,2017_접점비교!$N$5:$N$38,0)) -> 26.7 | I13: 7 | J13: =INDEX(2017_접점비교!$B$5:$B$38,MATCH(I13,2017_접점비교!$O$5:$O$38,0)) -> SNS, 블로그 사용자 후기 및 전문가 리뷰 | K13: =INDEX(2017_접점비교!$E$5:$E$38,MATCH(I13,2017_접점비교!$O$5:$O$38,0)) -> 23.4 | M13: 7 | N13: =INDEX(2017_접점비교!$B$5:$B$38,MATCH(M13,2017_접점비교!$P$5:$P$38,0)) -> 회사의 사회공헌 및 기여활동 | O13: =INDEX(2017_접점비교!$F$5:$F$38,MATCH(M13,2017_접점비교!$P$5:$P$38,0)) -> 29.133333
A14: 8 | B14: =INDEX(2017_접점비교!$B$5:$B$38,MATCH(A14,2017_접점비교!$M$5:$M$38,0)) -> 버스, 택시, 지하철 광고 | C14: =INDEX(2017_접점비교!$C$5:$C$38,MATCH(A14,2017_접점비교!$M$5:$M$38,0)) -> 35.1 | E14: 8 | F14: =INDEX(2017_접점비교!$B$5:$B$38,MATCH(E14,2017_접점비교!$N$5:$N$38,0)) -> 쿠폰/프로모션 등 행사 및 이벤트 | G14: =INDEX(2017_접점비교!$D$5:$D$38,MATCH(E14,2017_접점비교!$N$5:$N$38,0)) -> 26.3 | I14: 8 | J14: =INDEX(2017_접점비교!$B$5:$B$38,MATCH(I14,2017_접점비교!$O$5:$O$38,0)) -> 포털 카페 및 커뮤니티(네이버, 다음 등) | K14: =INDEX(2017_접점비교!$E$5:$E$38,MATCH(I14,2017_접점비교!$O$5:$O$38,0)) -> 22.9 | M14: 8 | N14: =INDEX(2017_접점비교!$B$5:$B$38,MATCH(M14,2017_접점비교!$P$5:$P$38,0)) -> 매장 내 광고(POP) | O14: =INDEX(2017_접점비교!$F$5:$F$38,MATCH(M14,2017_접점비교!$P$5:$P$38,0)) -> 25.933333
A15: 9 | B15: =INDEX(2017_접점비교!$B$5:$B$38,MATCH(A15,2017_접점비교!$M$5:$M$38,0)) -> SNS(페이스북, 인스타그램, 트위터 등) 광고/홍보 | C15: =INDEX(2017_접점비교!$C$5:$C$38,MATCH(A15,2017_접점비교!$M$5:$M$38,0)) -> 34.7 | E15: 9 | F15: =INDEX(2017_접점비교!$B$5:$B$38,MATCH(E15,2017_접점비교!$N$5:$N$38,0)) -> 건물 외벽/옥상, 역사 및 정류장 광고 | G15: =INDEX(2017_접점비교!$D$5:$D$38,MATCH(E15,2017_접점비교!$N$5:$N$38,0)) -> 25.8 | I15: 9 | J15: =INDEX(2017_접점비교!$B$5:$B$38,MATCH(I15,2017_접점비교!$O$5:$O$38,0)) -> 드라마 등 TV프로그램 속 간접광고(PPL) | K15: =INDEX(2017_접점비교!$E$5:$E$38,MATCH(I15,2017_접점비교!$O$5:$O$38,0)) -> 20.7 | M15: 9 | N15: =INDEX(2017_접점비교!$B$5:$B$38,MATCH(M15,2017_접점비교!$P$5:$P$38,0)) -> 포털 카페 및 커뮤니티(네이버, 다음 등) | O15: =INDEX(2017_접점비교!$F$5:$F$38,MATCH(M15,2017_접점비교!$P$5:$P$38,0)) -> 25.1
A16: 10 | B16: =INDEX(2017_접점비교!$B$5:$B$38,MATCH(A16,2017_접점비교!$M$5:$M$38,0)) -> 라디오 광고 | C16: =INDEX(2017_접점비교!$C$5:$C$38,MATCH(A16,2017_접점비교!$M$5:$M$38,0)) -> 34 | E16: 10 | F16: =INDEX(2017_접점비교!$B$5:$B$38,MATCH(E16,2017_접점비교!$N$5:$N$38,0)) -> 매장 내 광고(POP) | G16: =INDEX(2017_접점비교!$D$5:$D$38,MATCH(E16,2017_접점비교!$N$5:$N$38,0)) -> 25.5 | I16: 10 | J16: =INDEX(2017_접점비교!$B$5:$B$38,MATCH(I16,2017_접점비교!$O$5:$O$38,0)) -> 가격비교사이트 및 제품 관련 전문사이트 | K16: =INDEX(2017_접점비교!$E$5:$E$38,MATCH(I16,2017_접점비교!$O$5:$O$38,0)) -> 19.4 | M16: 10 | N16: =INDEX(2017_접점비교!$B$5:$B$38,MATCH(M16,2017_접점비교!$P$5:$P$38,0)) -> 가격비교사이트 및 제품 관련 전문사이트 | O16: =INDEX(2017_접점비교!$F$5:$F$38,MATCH(M16,2017_접점비교!$P$5:$P$38,0)) -> 23.766667
A20: 2018년
A21: 인지 | E21: 호감 | I21: 구매 | M21: 3단계 평균
A22: 순위 | B22: 접점 | C22: 비율(%) | E22: 순위 | F22: 접점 | G22: 비율(%) | I22: 순위 | J22: 접점 | K22: 비율(%) | M22: 순위 | N22: 접점 | O22: 비율(%)
A23: 1 | B23: =INDEX(2018_접점비교!$B$5:$B$38,MATCH(A23,2018_접점비교!$M$5:$M$38,0)) -> TV 광고 | C23: =INDEX(2018_접점비교!$C$5:$C$38,MATCH(A23,2018_접점비교!$M$5:$M$38,0)) -> 75.8 | E23: 1 | F23: =INDEX(2018_접점비교!$B$5:$B$38,MATCH(E23,2018_접점비교!$N$5:$N$38,0)) -> TV 광고 | G23: =INDEX(2018_접점비교!$D$5:$D$38,MATCH(E23,2018_접점비교!$N$5:$N$38,0)) -> 60.4 | I23: 1 | J23: =INDEX(2018_접점비교!$B$5:$B$38,MATCH(I23,2018_접점비교!$O$5:$O$38,0)) -> 주변사람(친구/가족/동료)의 추천 | K23: =INDEX(2018_접점비교!$E$5:$E$38,MATCH(I23,2018_접점비교!$O$5:$O$38,0)) -> 60.4 | M23: 1 | N23: =INDEX(2018_접점비교!$B$5:$B$38,MATCH(M23,2018_접점비교!$P$5:$P$38,0)) -> TV 광고 | O23: =INDEX(2018_접점비교!$F$5:$F$38,MATCH(M23,2018_접점비교!$P$5:$P$38,0)) -> 59.866667
A24: 2 | B24: =INDEX(2018_접점비교!$B$5:$B$38,MATCH(A24,2018_접점비교!$M$5:$M$38,0)) -> 주변사람(친구/가족/동료)의 추천 | C24: =INDEX(2018_접점비교!$C$5:$C$38,MATCH(A24,2018_접점비교!$M$5:$M$38,0)) -> 55.8 | E24: 2 | F24: =INDEX(2018_접점비교!$B$5:$B$38,MATCH(E24,2018_접점비교!$N$5:$N$38,0)) -> 주변사람(친구/가족/동료)의 추천 | G24: =INDEX(2018_접점비교!$D$5:$D$38,MATCH(E24,2018_접점비교!$N$5:$N$38,0)) -> 44 | I24: 2 | J24: =INDEX(2018_접점비교!$B$5:$B$38,MATCH(I24,2018_접점비교!$O$5:$O$38,0)) -> TV 광고 | K24: =INDEX(2018_접점비교!$E$5:$E$38,MATCH(I24,2018_접점비교!$O$5:$O$38,0)) -> 43.4 | M24: 2 | N24: =INDEX(2018_접점비교!$B$5:$B$38,MATCH(M24,2018_접점비교!$P$5:$P$38,0)) -> 주변사람(친구/가족/동료)의 추천 | O24: =INDEX(2018_접점비교!$F$5:$F$38,MATCH(M24,2018_접점비교!$P$5:$P$38,0)) -> 53.4
A25: 3 | B25: =INDEX(2018_접점비교!$B$5:$B$38,MATCH(A25,2018_접점비교!$M$5:$M$38,0)) -> 드라마 등 TV프로그램 속 간접광고(PPL) | C25: =INDEX(2018_접점비교!$C$5:$C$38,MATCH(A25,2018_접점비교!$M$5:$M$38,0)) -> 44.2 | E25: 3 | F25: =INDEX(2018_접점비교!$B$5:$B$38,MATCH(E25,2018_접점비교!$N$5:$N$38,0)) -> 드라마 등 TV프로그램 속 간접광고(PPL) | G25: =INDEX(2018_접점비교!$D$5:$D$38,MATCH(E25,2018_접점비교!$N$5:$N$38,0)) -> 36.3 | I25: 3 | J25: =INDEX(2018_접점비교!$B$5:$B$38,MATCH(I25,2018_접점비교!$O$5:$O$38,0)) -> 판매원(점원) 추천 | K25: =INDEX(2018_접점비교!$E$5:$E$38,MATCH(I25,2018_접점비교!$O$5:$O$38,0)) -> 41.2 | M25: 3 | N25: =INDEX(2018_접점비교!$B$5:$B$38,MATCH(M25,2018_접점비교!$P$5:$P$38,0)) -> 매장 내 진열제품 및 제품정보 | O25: =INDEX(2018_접점비교!$F$5:$F$38,MATCH(M25,2018_접점비교!$P$5:$P$38,0)) -> 35.9
A26: 4 | B26: =INDEX(2018_접점비교!$B$5:$B$38,MATCH(A26,2018_접점비교!$M$5:$M$38,0)) -> 건물 외벽/옥상, 역사 및 정류장 광고 | C26: =INDEX(2018_접점비교!$C$5:$C$38,MATCH(A26,2018_접점비교!$M$5:$M$38,0)) -> 42 | E26: 4 | F26: =INDEX(2018_접점비교!$B$5:$B$38,MATCH(E26,2018_접점비교!$N$5:$N$38,0)) -> 매장 내 진열제품 및 제품정보 | G26: =INDEX(2018_접점비교!$D$5:$D$38,MATCH(E26,2018_접점비교!$N$5:$N$38,0)) -> 34.9 | I26: 4 | J26: =INDEX(2018_접점비교!$B$5:$B$38,MATCH(I26,2018_접점비교!$O$5:$O$38,0)) -> 매장 내 진열제품 및 제품정보 | K26: =INDEX(2018_접점비교!$E$5:$E$38,MATCH(I26,2018_접점비교!$O$5:$O$38,0)) -> 33.3 | M26: 4 | N26: =INDEX(2018_접점비교!$B$5:$B$38,MATCH(M26,2018_접점비교!$P$5:$P$38,0)) -> 판매원(점원) 추천 | O26: =INDEX(2018_접점비교!$F$5:$F$38,MATCH(M26,2018_접점비교!$P$5:$P$38,0)) -> 35.466667
A27: 5 | B27: =INDEX(2018_접점비교!$B$5:$B$38,MATCH(A27,2018_접점비교!$M$5:$M$38,0)) -> 매장 내 진열제품 및 제품정보 | C27: =INDEX(2018_접점비교!$C$5:$C$38,MATCH(A27,2018_접점비교!$M$5:$M$38,0)) -> 39.5 | E27: 5 | F27: =INDEX(2018_접점비교!$B$5:$B$38,MATCH(E27,2018_접점비교!$N$5:$N$38,0)) -> 판매원(점원) 추천 | G27: =INDEX(2018_접점비교!$D$5:$D$38,MATCH(E27,2018_접점비교!$N$5:$N$38,0)) -> 27.7 | I27: 5 | J27: =INDEX(2018_접점비교!$B$5:$B$38,MATCH(I27,2018_접점비교!$O$5:$O$38,0)) -> 샘플/구매 사은품 | K27: =INDEX(2018_접점비교!$E$5:$E$38,MATCH(I27,2018_접점비교!$O$5:$O$38,0)) -> 29.1 | M27: 5 | N27: =INDEX(2018_접점비교!$B$5:$B$38,MATCH(M27,2018_접점비교!$P$5:$P$38,0)) -> 드라마 등 TV프로그램 속 간접광고(PPL) | O27: =INDEX(2018_접점비교!$F$5:$F$38,MATCH(M27,2018_접점비교!$P$5:$P$38,0)) -> 33.666667
A28: 6 | B28: =INDEX(2018_접점비교!$B$5:$B$38,MATCH(A28,2018_접점비교!$M$5:$M$38,0)) -> 매장 간판 및 외관 광고물 | C28: =INDEX(2018_접점비교!$C$5:$C$38,MATCH(A28,2018_접점비교!$M$5:$M$38,0)) -> 39.2 | E28: 6 | F28: =INDEX(2018_접점비교!$B$5:$B$38,MATCH(E28,2018_접점비교!$N$5:$N$38,0)) -> 샘플/구매 사은품 | G28: =INDEX(2018_접점비교!$D$5:$D$38,MATCH(E28,2018_접점비교!$N$5:$N$38,0)) -> 26.7 | I28: 6 | J28: =INDEX(2018_접점비교!$B$5:$B$38,MATCH(I28,2018_접점비교!$O$5:$O$38,0)) -> 쿠폰/프로모션 등 행사 및 이벤트 | K28: =INDEX(2018_접점비교!$E$5:$E$38,MATCH(I28,2018_접점비교!$O$5:$O$38,0)) -> 26.4 | M28: 6 | N28: =INDEX(2018_접점비교!$B$5:$B$38,MATCH(M28,2018_접점비교!$P$5:$P$38,0)) -> 제품 카달로그/전단지 | O28: =INDEX(2018_접점비교!$F$5:$F$38,MATCH(M28,2018_접점비교!$P$5:$P$38,0)) -> 27.8
A29: 7 | B29: =INDEX(2018_접점비교!$B$5:$B$38,MATCH(A29,2018_접점비교!$M$5:$M$38,0)) -> 판매원(점원) 추천 | C29: =INDEX(2018_접점비교!$C$5:$C$38,MATCH(A29,2018_접점비교!$M$5:$M$38,0)) -> 37.5 | E29: 7 | F29: =INDEX(2018_접점비교!$B$5:$B$38,MATCH(E29,2018_접점비교!$N$5:$N$38,0)) -> 제품 카달로그/전단지 | G29: =INDEX(2018_접점비교!$D$5:$D$38,MATCH(E29,2018_접점비교!$N$5:$N$38,0)) -> 26.1 | I29: 7 | J29: =INDEX(2018_접점비교!$B$5:$B$38,MATCH(I29,2018_접점비교!$O$5:$O$38,0)) -> SNS, 블로그 사용자 후기 및 전문가 리뷰 | K29: =INDEX(2018_접점비교!$E$5:$E$38,MATCH(I29,2018_접점비교!$O$5:$O$38,0)) -> 21 | M29: 7 | N29: =INDEX(2018_접점비교!$B$5:$B$38,MATCH(M29,2018_접점비교!$P$5:$P$38,0)) -> 샘플/구매 사은품 | O29: =INDEX(2018_접점비교!$F$5:$F$38,MATCH(M29,2018_접점비교!$P$5:$P$38,0)) -> 27.3
A30: 8 | B30: =INDEX(2018_접점비교!$B$5:$B$38,MATCH(A30,2018_접점비교!$M$5:$M$38,0)) -> 제품 카달로그/전단지 | C30: =INDEX(2018_접점비교!$C$5:$C$38,MATCH(A30,2018_접점비교!$M$5:$M$38,0)) -> 37 | E30: 8 | F30: =INDEX(2018_접점비교!$B$5:$B$38,MATCH(E30,2018_접점비교!$N$5:$N$38,0)) -> 쿠폰/프로모션 등 행사 및 이벤트 | G30: =INDEX(2018_접점비교!$D$5:$D$38,MATCH(E30,2018_접점비교!$N$5:$N$38,0)) -> 26.1 | I30: 8 | J30: =INDEX(2018_접점비교!$B$5:$B$38,MATCH(I30,2018_접점비교!$O$5:$O$38,0)) -> 드라마 등 TV프로그램 속 간접광고(PPL) | K30: =INDEX(2018_접점비교!$E$5:$E$38,MATCH(I30,2018_접점비교!$O$5:$O$38,0)) -> 20.5 | M30: 8 | N30: =INDEX(2018_접점비교!$B$5:$B$38,MATCH(M30,2018_접점비교!$P$5:$P$38,0)) -> 쿠폰/프로모션 등 행사 및 이벤트 | O30: =INDEX(2018_접점비교!$F$5:$F$38,MATCH(M30,2018_접점비교!$P$5:$P$38,0)) -> 26.033333
A31: 9 | B31: =INDEX(2018_접점비교!$B$5:$B$38,MATCH(A31,2018_접점비교!$M$5:$M$38,0)) -> 버스, 택시, 지하철 광고 | C31: =INDEX(2018_접점비교!$C$5:$C$38,MATCH(A31,2018_접점비교!$M$5:$M$38,0)) -> 36.5 | E31: 9 | F31: =INDEX(2018_접점비교!$B$5:$B$38,MATCH(E31,2018_접점비교!$N$5:$N$38,0)) -> 매장 내 광고(POP) | G31: =INDEX(2018_접점비교!$D$5:$D$38,MATCH(E31,2018_접점비교!$N$5:$N$38,0)) -> 23.9 | I31: 9 | J31: =INDEX(2018_접점비교!$B$5:$B$38,MATCH(I31,2018_접점비교!$O$5:$O$38,0)) -> 제품 카달로그/전단지 | K31: =INDEX(2018_접점비교!$E$5:$E$38,MATCH(I31,2018_접점비교!$O$5:$O$38,0)) -> 20.3 | M31: 9 | N31: =INDEX(2018_접점비교!$B$5:$B$38,MATCH(M31,2018_접점비교!$P$5:$P$38,0)) -> 매장 내 광고(POP) | O31: =INDEX(2018_접점비교!$F$5:$F$38,MATCH(M31,2018_접점비교!$P$5:$P$38,0)) -> 24.833333
A32: 10 | B32: =INDEX(2018_접점비교!$B$5:$B$38,MATCH(A32,2018_접점비교!$M$5:$M$38,0)) -> 매장 내 광고(POP) | C32: =INDEX(2018_접점비교!$C$5:$C$38,MATCH(A32,2018_접점비교!$M$5:$M$38,0)) -> 35.9 | E32: 10 | F32: =INDEX(2018_접점비교!$B$5:$B$38,MATCH(E32,2018_접점비교!$N$5:$N$38,0)) -> 영화관, 스포츠 경기장, 공연장 등 광고 | G32: =INDEX(2018_접점비교!$D$5:$D$38,MATCH(E32,2018_접점비교!$N$5:$N$38,0)) -> 22.5 | I32: 10 | J32: =INDEX(2018_접점비교!$B$5:$B$38,MATCH(I32,2018_접점비교!$O$5:$O$38,0)) -> 가격비교사이트 및 제품 관련 전문사이트 | K32: =INDEX(2018_접점비교!$E$5:$E$38,MATCH(I32,2018_접점비교!$O$5:$O$38,0)) -> 19.3 | M32: 10 | N32: =INDEX(2018_접점비교!$B$5:$B$38,MATCH(M32,2018_접점비교!$P$5:$P$38,0)) -> 매장 간판 및 외관 광고물 | O32: =INDEX(2018_접점비교!$F$5:$F$38,MATCH(M32,2018_접점비교!$P$5:$P$38,0)) -> 23.866667
A36: 2019년
A37: 인지 | E37: 호감 | I37: 구매 | M37: 3단계 평균
A38: 순위 | B38: 접점 | C38: 비율(%) | E38: 순위 | F38: 접점 | G38: 비율(%) | I38: 순위 | J38: 접점 | K38: 비율(%) | M38: 순위 | N38: 접점 | O38: 비율(%)
A39: 1 | B39: =INDEX(2019_접점비교!$B$5:$B$38,MATCH(A39,2019_접점비교!$M$5:$M$38,0)) -> TV 광고 | C39: =INDEX(2019_접점비교!$C$5:$C$38,MATCH(A39,2019_접점비교!$M$5:$M$38,0)) -> 82.3 | E39: 1 | F39: =INDEX(2019_접점비교!$B$5:$B$38,MATCH(E39,2019_접점비교!$N$5:$N$38,0)) -> TV 광고 | G39: =INDEX(2019_접점비교!$D$5:$D$38,MATCH(E39,2019_접점비교!$N$5:$N$38,0)) -> 58.4 | I39: 1 | J39: =INDEX(2019_접점비교!$B$5:$B$38,MATCH(I39,2019_접점비교!$O$5:$O$38,0)) -> 주변사람(친구/가족/동료)의 추천 | K39: =INDEX(2019_접점비교!$E$5:$E$38,MATCH(I39,2019_접점비교!$O$5:$O$38,0)) -> 68.2 | M39: 1 | N39: =INDEX(2019_접점비교!$B$5:$B$38,MATCH(M39,2019_접점비교!$P$5:$P$38,0)) -> TV 광고 | O39: =INDEX(2019_접점비교!$F$5:$F$38,MATCH(M39,2019_접점비교!$P$5:$P$38,0)) -> 62.6
A40: 2 | B40: =INDEX(2019_접점비교!$B$5:$B$38,MATCH(A40,2019_접점비교!$M$5:$M$38,0)) -> 주변사람(친구/가족/동료)의 추천 | C40: =INDEX(2019_접점비교!$C$5:$C$38,MATCH(A40,2019_접점비교!$M$5:$M$38,0)) -> 58.5 | E40: 2 | F40: =INDEX(2019_접점비교!$B$5:$B$38,MATCH(E40,2019_접점비교!$N$5:$N$38,0)) -> 주변사람(친구/가족/동료)의 추천 | G40: =INDEX(2019_접점비교!$D$5:$D$38,MATCH(E40,2019_접점비교!$N$5:$N$38,0)) -> 49.7 | I40: 2 | J40: =INDEX(2019_접점비교!$B$5:$B$38,MATCH(I40,2019_접점비교!$O$5:$O$38,0)) -> TV 광고 | K40: =INDEX(2019_접점비교!$E$5:$E$38,MATCH(I40,2019_접점비교!$O$5:$O$38,0)) -> 47.1 | M40: 2 | N40: =INDEX(2019_접점비교!$B$5:$B$38,MATCH(M40,2019_접점비교!$P$5:$P$38,0)) -> 주변사람(친구/가족/동료)의 추천 | O40: =INDEX(2019_접점비교!$F$5:$F$38,MATCH(M40,2019_접점비교!$P$5:$P$38,0)) -> 58.8
A41: 3 | B41: =INDEX(2019_접점비교!$B$5:$B$38,MATCH(A41,2019_접점비교!$M$5:$M$38,0)) -> 매장 내 진열제품 및 제품정보 | C41: =INDEX(2019_접점비교!$C$5:$C$38,MATCH(A41,2019_접점비교!$M$5:$M$38,0)) -> 44.8 | E41: 3 | F41: =INDEX(2019_접점비교!$B$5:$B$38,MATCH(E41,2019_접점비교!$N$5:$N$38,0)) -> 매장 내 진열제품 및 제품정보 | G41: =INDEX(2019_접점비교!$D$5:$D$38,MATCH(E41,2019_접점비교!$N$5:$N$38,0)) -> 36.4 | I41: 3 | J41: =INDEX(2019_접점비교!$B$5:$B$38,MATCH(I41,2019_접점비교!$O$5:$O$38,0)) -> 판매원(점원) 추천 | K41: =INDEX(2019_접점비교!$E$5:$E$38,MATCH(I41,2019_접점비교!$O$5:$O$38,0)) -> 43.4 | M41: 3 | N41: =INDEX(2019_접점비교!$B$5:$B$38,MATCH(M41,2019_접점비교!$P$5:$P$38,0)) -> 판매원(점원) 추천 | O41: =INDEX(2019_접점비교!$F$5:$F$38,MATCH(M41,2019_접점비교!$P$5:$P$38,0)) -> 39.133333
A42: 4 | B42: =INDEX(2019_접점비교!$B$5:$B$38,MATCH(A42,2019_접점비교!$M$5:$M$38,0)) -> 건물 외벽/옥상, 역사 및 정류장 광고 | C42: =INDEX(2019_접점비교!$C$5:$C$38,MATCH(A42,2019_접점비교!$M$5:$M$38,0)) -> 44.6 | E42: 4 | F42: =INDEX(2019_접점비교!$B$5:$B$38,MATCH(E42,2019_접점비교!$N$5:$N$38,0)) -> 드라마 등 TV프로그램 속 간접광고(PPL) | G42: =INDEX(2019_접점비교!$D$5:$D$38,MATCH(E42,2019_접점비교!$N$5:$N$38,0)) -> 34.8 | I42: 4 | J42: =INDEX(2019_접점비교!$B$5:$B$38,MATCH(I42,2019_접점비교!$O$5:$O$38,0)) -> 매장 내 진열제품 및 제품정보 | K42: =INDEX(2019_접점비교!$E$5:$E$38,MATCH(I42,2019_접점비교!$O$5:$O$38,0)) -> 34.2 | M42: 4 | N42: =INDEX(2019_접점비교!$B$5:$B$38,MATCH(M42,2019_접점비교!$P$5:$P$38,0)) -> 매장 내 진열제품 및 제품정보 | O42: =INDEX(2019_접점비교!$F$5:$F$38,MATCH(M42,2019_접점비교!$P$5:$P$38,0)) -> 38.466667
A43: 5 | B43: =INDEX(2019_접점비교!$B$5:$B$38,MATCH(A43,2019_접점비교!$M$5:$M$38,0)) -> 버스, 택시, 지하철 광고 | C43: =INDEX(2019_접점비교!$C$5:$C$38,MATCH(A43,2019_접점비교!$M$5:$M$38,0)) -> 43 | E43: 5 | F43: =INDEX(2019_접점비교!$B$5:$B$38,MATCH(E43,2019_접점비교!$N$5:$N$38,0)) -> 판매원(점원) 추천 | G43: =INDEX(2019_접점비교!$D$5:$D$38,MATCH(E43,2019_접점비교!$N$5:$N$38,0)) -> 31 | I43: 5 | J43: =INDEX(2019_접점비교!$B$5:$B$38,MATCH(I43,2019_접점비교!$O$5:$O$38,0)) -> 샘플/구매 사은품 | K43: =INDEX(2019_접점비교!$E$5:$E$38,MATCH(I43,2019_접점비교!$O$5:$O$38,0)) -> 31.3 | M43: 5 | N43: =INDEX(2019_접점비교!$B$5:$B$38,MATCH(M43,2019_접점비교!$P$5:$P$38,0)) -> 드라마 등 TV프로그램 속 간접광고(PPL) | O43: =INDEX(2019_접점비교!$F$5:$F$38,MATCH(M43,2019_접점비교!$P$5:$P$38,0)) -> 31.433333
A44: 6 | B44: =INDEX(2019_접점비교!$B$5:$B$38,MATCH(A44,2019_접점비교!$M$5:$M$38,0)) -> 판매원(점원) 추천 | C44: =INDEX(2019_접점비교!$C$5:$C$38,MATCH(A44,2019_접점비교!$M$5:$M$38,0)) -> 43 | E44: 6 | F44: =INDEX(2019_접점비교!$B$5:$B$38,MATCH(E44,2019_접점비교!$N$5:$N$38,0)) -> 샘플/구매 사은품 | G44: =INDEX(2019_접점비교!$D$5:$D$38,MATCH(E44,2019_접점비교!$N$5:$N$38,0)) -> 29.6 | I44: 6 | J44: =INDEX(2019_접점비교!$B$5:$B$38,MATCH(I44,2019_접점비교!$O$5:$O$38,0)) -> 쿠폰/프로모션 등 행사 및 이벤트 | K44: =INDEX(2019_접점비교!$E$5:$E$38,MATCH(I44,2019_접점비교!$O$5:$O$38,0)) -> 31.2 | M44: 6 | N44: =INDEX(2019_접점비교!$B$5:$B$38,MATCH(M44,2019_접점비교!$P$5:$P$38,0)) -> 샘플/구매 사은품 | O44: =INDEX(2019_접점비교!$F$5:$F$38,MATCH(M44,2019_접점비교!$P$5:$P$38,0)) -> 30.933333
A45: 7 | B45: =INDEX(2019_접점비교!$B$5:$B$38,MATCH(A45,2019_접점비교!$M$5:$M$38,0)) -> 드라마 등 TV프로그램 속 간접광고(PPL) | C45: =INDEX(2019_접점비교!$C$5:$C$38,MATCH(A45,2019_접점비교!$M$5:$M$38,0)) -> 42.4 | E45: 7 | F45: =INDEX(2019_접점비교!$B$5:$B$38,MATCH(E45,2019_접점비교!$N$5:$N$38,0)) -> 쿠폰/프로모션 등 행사 및 이벤트 | G45: =INDEX(2019_접점비교!$D$5:$D$38,MATCH(E45,2019_접점비교!$N$5:$N$38,0)) -> 28.3 | I45: 7 | J45: =INDEX(2019_접점비교!$B$5:$B$38,MATCH(I45,2019_접점비교!$O$5:$O$38,0)) -> SNS, 블로그 사용자 후기 및 전문가 리뷰 | K45: =INDEX(2019_접점비교!$E$5:$E$38,MATCH(I45,2019_접점비교!$O$5:$O$38,0)) -> 24.6 | M45: 7 | N45: =INDEX(2019_접점비교!$B$5:$B$38,MATCH(M45,2019_접점비교!$P$5:$P$38,0)) -> 쿠폰/프로모션 등 행사 및 이벤트 | O45: =INDEX(2019_접점비교!$F$5:$F$38,MATCH(M45,2019_접점비교!$P$5:$P$38,0)) -> 29.8
A46: 8 | B46: =INDEX(2019_접점비교!$B$5:$B$38,MATCH(A46,2019_접점비교!$M$5:$M$38,0)) -> 제품 카달로그/전단지 | C46: =INDEX(2019_접점비교!$C$5:$C$38,MATCH(A46,2019_접점비교!$M$5:$M$38,0)) -> 41.5 | E46: 8 | F46: =INDEX(2019_접점비교!$B$5:$B$38,MATCH(E46,2019_접점비교!$N$5:$N$38,0)) -> 제품 카달로그/전단지 | G46: =INDEX(2019_접점비교!$D$5:$D$38,MATCH(E46,2019_접점비교!$N$5:$N$38,0)) -> 26.7 | I46: 8 | J46: =INDEX(2019_접점비교!$B$5:$B$38,MATCH(I46,2019_접점비교!$O$5:$O$38,0)) -> 가격비교사이트 및 제품 관련 전문사이트 | K46: =INDEX(2019_접점비교!$E$5:$E$38,MATCH(I46,2019_접점비교!$O$5:$O$38,0)) -> 20.2 | M46: 8 | N46: =INDEX(2019_접점비교!$B$5:$B$38,MATCH(M46,2019_접점비교!$P$5:$P$38,0)) -> 제품 카달로그/전단지 | O46: =INDEX(2019_접점비교!$F$5:$F$38,MATCH(M46,2019_접점비교!$P$5:$P$38,0)) -> 29.266667
A47: 9 | B47: =INDEX(2019_접점비교!$B$5:$B$38,MATCH(A47,2019_접점비교!$M$5:$M$38,0)) -> 매장 간판 및 외관 광고물 | C47: =INDEX(2019_접점비교!$C$5:$C$38,MATCH(A47,2019_접점비교!$M$5:$M$38,0)) -> 40 | E47: 9 | F47: =INDEX(2019_접점비교!$B$5:$B$38,MATCH(E47,2019_접점비교!$N$5:$N$38,0)) -> SNS, 블로그 사용자 후기 및 전문가 리뷰 | G47: =INDEX(2019_접점비교!$D$5:$D$38,MATCH(E47,2019_접점비교!$N$5:$N$38,0)) -> 24.5 | I47: 9 | J47: =INDEX(2019_접점비교!$B$5:$B$38,MATCH(I47,2019_접점비교!$O$5:$O$38,0)) -> 제품 카달로그/전단지 | K47: =INDEX(2019_접점비교!$E$5:$E$38,MATCH(I47,2019_접점비교!$O$5:$O$38,0)) -> 19.6 | M47: 9 | N47: =INDEX(2019_접점비교!$B$5:$B$38,MATCH(M47,2019_접점비교!$P$5:$P$38,0)) -> SNS, 블로그 사용자 후기 및 전문가 리뷰 | O47: =INDEX(2019_접점비교!$F$5:$F$38,MATCH(M47,2019_접점비교!$P$5:$P$38,0)) -> 25.9
...

Sheet 순위_안정성
A1: 접점별 3개년 순위 변화와 평균
A2: 순위는 각 연도 '접점비교' 시트에서 가져옴(1=가장 높음). 변동폭이 작을수록 해마다 일관된 영향력. 2018~2019 평균은 2017→2018 설문 개편 가능성을 피하기 위한 보조 지표.
A4: 구분 | B4: 접점(매체) | C4: 인지 순위 | F4: 호감 순위 | I4: 구매 순위 | L4: 구매 순위 변동폭 | M4: 구매 자료 연수 | N4: 구매 3개년 평균(%) | O4: 구매 2018~19 평균(%) | P4: 2018~19 평균 순위 | Q4: 고유순위·3개년 | R4: 고유순위·18~19
C5: 2017 | D5: 2018 | E5: 2019 | F5: 2017 | G5: 2018 | H5: 2019 | I5: 2017 | J5: 2018 | K5: 2019
